<sdf version='1.11'>
  <model name='devol'>
    <joint name='base_joint' type='fixed'>
      <pose relative_to='__model__'>0 0 0 0 0 0</pose>
      <parent>world</parent>
      <child>base_link</child>
    </joint>
    <link name='base_link'>
      <pose relative_to='base_joint'>0 0 0 0 0 0</pose>
      <inertial>
        <pose>0 0 0 0 0 0</pose>
        <mass>4</mass>
        <inertia>
          <ixx>0.0061063308907999998</ixx>
          <ixy>0</ixy>
          <ixz>0</ixz>
          <iyy>0.0061063308907999998</iyy>
          <iyz>0</iyz>
          <izz>0.01125</izz>
        </inertia>
      </inertial>
      <collision name='base_link_inertia_collision'>
        <pose>0 0 0 0 0 -2.4492935982947059e-16</pose>
        <geometry>
          <mesh>
            <scale>1 1 1</scale>
            <uri>/opt/ros/jazzy/share/ur_description/meshes/ur20/collision/base.stl</uri>
          </mesh>
        </geometry>
      </collision>
      <visual name='base_link_inertia_visual'>
        <pose>0 0 0 0 0 -2.4492935982947059e-16</pose>
        <geometry>
          <mesh>
            <scale>1 1 1</scale>
            <uri>/opt/ros/jazzy/share/ur_description/meshes/ur20/visual/base.dae</uri>
          </mesh>
        </geometry>
      </visual>
    </link>
    <joint name='shoulder_pan_joint' type='revolute'>
      <pose relative_to='base_link'>0 0 0.23630000000000001 0 0 3.1415926535897931</pose>
      <parent>base_link</parent>
      <child>shoulder_link</child>
      <axis>
        <xyz>0 0 1</xyz>
        <limit>
          <lower>-6.2831853071795862</lower>
          <upper>6.2831853071795862</upper>
          <effort>738</effort>
          <velocity>2.0943951023931948</velocity>
        </limit>
        <dynamics>
          <damping>0</damping>
          <friction>0</friction>
          <spring_reference>0</spring_reference>
          <spring_stiffness>0</spring_stiffness>
        </dynamics>
      </axis>
    </joint>
    <link name='shoulder_link'>
      <pose relative_to='shoulder_pan_joint'>0 0 0 0 0 0</pose>
      <inertial>
        <pose>0 -0.0061999999999999998 -0.060999999999999999 1.570796326794897 0 0</pose>
        <mass>16.343</mass>
        <inertia>
          <ixx>0.088660000000000003</ixx>
          <ixy>-0.00011</ixy>
          <ixz>-0.00011</ixz>
          <iyy>0.076319999999999999</iyy>
          <iyz>0.0071999999999999998</iyz>
          <izz>0.084180000000000005</izz>
        </inertia>
      </inertial>
      <collision name='shoulder_link_collision'>
        <pose>0 0 0 0 0 3.1415926535897931</pose>
        <geometry>
          <mesh>
            <scale>1 1 1</scale>
            <uri>/opt/ros/jazzy/share/ur_description/meshes/ur20/collision/shoulder.stl</uri>
          </mesh>
        </geometry>
      </collision>
      <visual name='shoulder_link_visual'>
        <pose>0 0 0 0 0 3.1415926535897931</pose>
        <geometry>
          <mesh>
            <scale>1 1 1</scale>
            <uri>/opt/ros/jazzy/share/ur_description/meshes/ur20/visual/shoulder.dae</uri>
          </mesh>
        </geometry>
      </visual>
    </link>
    <joint name='shoulder_lift_joint' type='revolute'>
      <pose relative_to='shoulder_link'>0 0 0 1.5707963270000003 0 0</pose>
      <parent>shoulder_link</parent>
      <child>upper_arm_link</child>
      <axis>
        <xyz>0 0 1</xyz>
        <limit>
          <lower>-6.2831853071795862</lower>
          <upper>6.2831853071795862</upper>
          <effort>738</effort>
          <velocity>2.0943951023931948</velocity>
        </limit>
        <dynamics>
          <damping>0</damping>
          <friction>0</friction>
          <spring_reference>0</spring_reference>
          <spring_stiffness>0</spring_stiffness>
        </dynamics>
      </axis>
    </joint>
    <link name='upper_arm_link'>
      <pose relative_to='shoulder_lift_joint'>0 0 0 0 0 0</pose>
      <inertial>
        <pose>-0.33939999999999998 0 0.20979999999999999 0 0 0</pose>
        <mass>29.632000000000001</mass>
        <inertia>
          <ixx>0.1467</ixx>
          <ixy>0.00019000000000000001</ixy>
          <ixz>-0.051630000000000002</ixz>
          <iyy>4.6658999999999997</iyy>
          <iyz>4.0000000000000003e-05</iyz>
          <izz>4.6348000000000003</izz>
        </inertia>
      </inertial>
      <collision name='upper_arm_link_collision'>
        <pose>0 0 0.26000000000000001 1.5707963267948959 5.5511151231257827e-17 -1.5707963267948959</pose>
        <geometry>
          <mesh>
            <scale>1 1 1</scale>
            <uri>/opt/ros/jazzy/share/ur_description/meshes/ur20/collision/upperarm.stl</uri>
          </mesh>
        </geometry>
      </collision>
      <visual name='upper_arm_link_visual'>
        <pose>0 0 0.26000000000000001 1.5707963267948959 5.5511151231257827e-17 -1.5707963267948959</pose>
        <geometry>
          <mesh>
            <scale>1 1 1</scale>
            <uri>/opt/ros/jazzy/share/ur_description/meshes/ur20/visual/upperarm.dae</uri>
          </mesh>
        </geometry>
      </visual>
    </link>
    <joint name='elbow_joint' type='revolute'>
      <pose relative_to='upper_arm_link'>-0.86199999999999999 0 0 0 0 0</pose>
      <parent>upper_arm_link</parent>
      <child>forearm_link</child>
      <axis>
        <xyz>0 0 1</xyz>
        <limit>
          <lower>-3.1415926535897931</lower>
          <upper>3.1415926535897931</upper>
          <effort>433</effort>
          <velocity>2.617993877991494</velocity>
        </limit>
        <dynamics>
          <damping>0</damping>
          <friction>0</friction>
          <spring_reference>0</spring_reference>
          <spring_stiffness>0</spring_stiffness>
        </dynamics>
      </axis>
    </joint>
    <link name='forearm_link'>
      <pose relative_to='elbow_joint'>0 0 0 0 0 0</pose>
      <inertial>
        <pose>-0.40529999999999999 0 0.060400000000000002 0 0 0</pose>
        <mass>7.8789999999999996</mass>
        <inertia>
          <ixx>0.026120000000000001</ixx>
          <ixy>-5.0000000000000002e-05</ixy>
          <ixz>-0.028979999999999999</ixz>
          <iyy>0.75763000000000003</iyy>
          <iyz>-1.0000000000000001e-05</iyz>
          <izz>0.75327</izz>
        </inertia>
      </inertial>
      <collision name='forearm_link_collision'>
        <pose>0 0 0.042999999999999997 1.5707963267948959 5.5511151231257827e-17 -1.5707963267948959</pose>
        <geometry>
          <mesh>
            <scale>1 1 1</scale>
            <uri>/opt/ros/jazzy/share/ur_description/meshes/ur20/collision/forearm.stl</uri>
          </mesh>
        </geometry>
      </collision>
      <visual name='forearm_link_visual'>
        <pose>0 0 0.042999999999999997 1.5707963267948959 5.5511151231257827e-17 -1.5707963267948959</pose>
        <geometry>
          <mesh>
            <scale>1 1 1</scale>
            <uri>/opt/ros/jazzy/share/ur_description/meshes/ur20/visual/forearm.dae</uri>
          </mesh>
        </geometry>
      </visual>
    </link>
    <joint name='wrist_1_joint' type='revolute'>
      <pose relative_to='forearm_link'>-0.72870000000000001 0 0.20100000000000001 0 0 0</pose>
      <parent>forearm_link</parent>
      <child>wrist_1_link</child>
      <axis>
        <xyz>0 0 1</xyz>
        <limit>
          <lower>-6.2831853071795862</lower>
          <upper>6.2831853071795862</upper>
          <effort>107</effort>
          <velocity>3.6651914291880918</velocity>
        </limit>
        <dynamics>
          <damping>0</damping>
          <friction>0</friction>
          <spring_reference>0</spring_reference>
          <spring_stiffness>0</spring_stiffness>
        </dynamics>
      </axis>
    </joint>
    <link name='wrist_1_link'>
      <pose relative_to='wrist_1_joint'>0 0 0 0 0 0</pose>
      <inertial>
        <pose>0 -0.039300000000000002 -0.0025999999999999999 1.570796326794897 0 0</pose>
        <mass>3.0539999999999998</mass>
        <inertia>
          <ixx>0.0055500000000000002</ixx>
          <ixy>-1.0000000000000001e-05</ixy>
          <ixz>-2.0000000000000002e-05</ixz>
          <iyy>0.0053699999999999998</iyy>
          <iyz>0.00036000000000000002</iyz>
          <izz>0.0040200000000000001</izz>
        </inertia>
      </inertial>
      <collision name='wrist_1_link_collision'>
        <pose>0 0 -0.077499999999999999 1.5707963267948959 0 0</pose>
        <geometry>
          <mesh>
            <scale>1 1 1</scale>
            <uri>/opt/ros/jazzy/share/ur_description/meshes/ur20/collision/wrist1.stl</uri>
          </mesh>
        </geometry>
      </collision>
      <visual name='wrist_1_link_visual'>
        <pose>0 0 -0.077499999999999999 1.5707963267948959 0 0</pose>
        <geometry>
          <mesh>
            <scale>1 1 1</scale>
            <uri>/opt/ros/jazzy/share/ur_description/meshes/ur20/visual/wrist1.dae</uri>
          </mesh>
        </geometry>
      </visual>
    </link>
    <joint name='wrist_2_joint' type='revolute'>
      <pose relative_to='wrist_1_link'>0 -0.1593 -3.2672976162492252e-11 1.5707963270000003 0 0</pose>
      <parent>wrist_1_link</parent>
      <child>wrist_2_link</child>
      <axis>
        <xyz>0 0 1</xyz>
        <limit>
          <lower>-6.2831853071795862</lower>
          <upper>6.2831853071795862</upper>
          <effort>107</effort>
          <velocity>3.6651914291880918</velocity>
        </limit>
        <dynamics>
          <damping>0</damping>
          <friction>0</friction>
          <spring_reference>0</spring_reference>
          <spring_stiffness>0</spring_stiffness>
        </dynamics>
      </axis>
    </joint>
    <link name='wrist_2_link'>
      <pose relative_to='wrist_2_joint'>0 0 0 0 0 0</pose>
      <inertial>
        <pose>0 0.037900000000000003 -0.0023999999999999998 -1.570796326794897 0 0</pose>
        <mass>3.1259999999999999</mass>
        <inertia>
          <ixx>0.0058599999999999998</ixx>
          <ixy>-1.0000000000000001e-05</ixy>
          <ixz>-2.0000000000000002e-05</ixz>
          <iyy>0.0057800000000000004</iyy>
          <iyz>-0.00036999999999999999</iyz>
          <izz>0.0042700000000000004</izz>
        </inertia>
      </inertial>
      <collision name='wrist_2_link_collision'>
        <pose>0 0 -0.074899999999999994 0 0 0</pose>
        <geometry>
          <mesh>
            <scale>1 1 1</scale>
            <uri>/opt/ros/jazzy/share/ur_description/meshes/ur20/collision/wrist2.stl</uri>
          </mesh>
        </geometry>
      </collision>
      <visual name='wrist_2_link_visual'>
        <pose>0 0 -0.074899999999999994 0 0 0</pose>
        <geometry>
          <mesh>
            <scale>1 1 1</scale>
            <uri>/opt/ros/jazzy/share/ur_description/meshes/ur20/visual/wrist2.dae</uri>
          </mesh>
        </geometry>
      </visual>
    </link>
    <joint name='wrist_3_joint' type='revolute'>
      <pose relative_to='wrist_2_link'>0 0.15429999999999999 -3.1647459019915603e-11 -1.5707963270000003 1.2246467991473527e-16 -1.224646799147353e-16</pose>
      <parent>wrist_2_link</parent>
      <child>wrist_3_link</child>
      <axis>
        <xyz>0 0 1</xyz>
        <limit>
          <lower>-6.2831853071795862</lower>
          <upper>6.2831853071795862</upper>
          <effort>107</effort>
          <velocity>3.6651914291880918</velocity>
        </limit>
        <dynamics>
          <damping>0</damping>
          <friction>0</friction>
          <spring_reference>0</spring_reference>
          <spring_stiffness>0</spring_stiffness>
        </dynamics>
      </axis>
    </joint>
    <link name='wrist_3_link'>
      <pose relative_to='wrist_3_joint'>0 0 0 0 0 0</pose>
      <inertial>
        <pose>-5.0921236482016421e-18 9.4304616181822113e-06 0.00100051112497917 0 0 0</pose>
        <mass>1.59920197</mass>
        <inertia>
          <ixx>0.0035182844259568349</ixx>
          <ixy>2.935999999998467e-08</ixy>
          <ixz>3.8397829451883528e-19</ixz>
          <iyy>0.0035631281452328549</iyy>
          <iyz>-9.6123265111148962e-07</iyz>
          <izz>0.001591627960723981</izz>
        </inertia>
      </inertial>
      <collision name='wrist_3_link_collision'>
        <pose>0 0 -0.070000000000000007 1.5707963267948959 0 0</pose>
        <geometry>
          <mesh>
            <scale>1 1 1</scale>
            <uri>/opt/ros/jazzy/share/ur_description/meshes/ur20/collision/wrist3.stl</uri>
          </mesh>
        </geometry>
      </collision>
      <collision name='wrist_3_link_fixed_joint_lump__ur_to_robotiq_link_collision_1'>
        <pose>0 0 0 -2.4651903288156619e-32 -2.2204460492503131e-16 2.2204460492503131e-16</pose>
        <geometry>
          <mesh>
            <scale>1 1 1</scale>
            <uri>/opt/ros/jazzy/share/robotiq_description/meshes/collision/ur_to_robotiq_adapter.stl</uri>
          </mesh>
        </geometry>
      </collision>
      <collision name='wrist_3_link_fixed_joint_lump__robotiq_85_base_link_collision_2'>
        <pose>-1.7347234759768071e-18 0 0.010999999999999999 -2.4651903288156619e-32 -2.2204460492503131e-16 2.2204460492503131e-16</pose>
        <geometry>
          <mesh>
            <scale>1 1 1</scale>
            <uri>file:///opt/ros/jazzy/share/robotiq_description/meshes/collision/robotiq_base.stl</uri>
          </mesh>
        </geometry>
      </collision>
      <visual name='wrist_3_link_visual'>
        <pose>0 0 -0.070000000000000007 1.5707963267948959 0 0</pose>
        <geometry>
          <mesh>
            <scale>1 1 1</scale>
            <uri>/opt/ros/jazzy/share/ur_description/meshes/ur20/visual/wrist3.dae</uri>
          </mesh>
        </geometry>
      </visual>
      <visual name='wrist_3_link_fixed_joint_lump__ur_to_robotiq_link_visual_1'>
        <pose>0 0 0 -2.4651903288156619e-32 -2.2204460492503131e-16 2.2204460492503131e-16</pose>
        <geometry>
          <mesh>
            <scale>1 1 1</scale>
            <uri>/opt/ros/jazzy/share/robotiq_description/meshes/visual/ur_to_robotiq_adapter.dae</uri>
          </mesh>
        </geometry>
      </visual>
      <visual name='wrist_3_link_fixed_joint_lump__robotiq_85_base_link_visual_2'>
        <pose>-1.7347234759768071e-18 0 0.010999999999999999 -2.4651903288156619e-32 -2.2204460492503131e-16 2.2204460492503131e-16</pose>
        <geometry>
          <mesh>
            <scale>1 1 1</scale>
            <uri>file:///opt/ros/jazzy/share/robotiq_description/meshes/visual/robotiq_base.dae</uri>
          </mesh>
        </geometry>
      </visual>
    </link>
    <joint name='robotiq_85_left_inner_knuckle_joint' type='revolute'>
      <pose relative_to='wrist_3_link'>0.01269999999999998 3.4694469519536142e-18 0.072420000000000012 -2.4651903288156619e-32 -2.2204460492503131e-16 2.2204460492503131e-16</pose>
      <parent>wrist_3_link</parent>
      <child>robotiq_85_left_inner_knuckle_link</child>
      <axis>
        <xyz>0 -1 0</xyz>
        <mimic joint='robotiq_85_left_knuckle_joint'>
          <multiplier>1</multiplier>
          <offset>0</offset>
          <reference>0</reference>
        </mimic>
        <limit>
          <lower>-inf</lower>
          <upper>inf</upper>
        </limit>
        <dynamics>
          <spring_reference>0</spring_reference>
          <spring_stiffness>0</spring_stiffness>
        </dynamics>
      </axis>
    </joint>
    <link name='robotiq_85_left_inner_knuckle_link'>
      <pose relative_to='robotiq_85_left_inner_knuckle_joint'>0 0 0 0 0 0</pose>
      <inertial>
        <pose>0.018976989999999999 0.00015001000000000001 0.02247101 0 0 0</pose>
        <mass>0.029693764479999999</mass>
        <inertia>
          <ixx>9.5713600000000001e-06</ixx>
          <ixy>0</ixy>
          <ixz>-3.9342399999999998e-06</ixz>
          <iyy>8.69056e-06</iyy>
          <iyz>0</iyz>
          <izz>8.1914400000000003e-06</izz>
        </inertia>
      </inertial>
      <collision name='robotiq_85_left_inner_knuckle_link_collision'>
        <pose>0 0 0 0 0 0</pose>
        <geometry>
          <mesh>
            <scale>1 1 1</scale>
            <uri>file:///opt/ros/jazzy/share/robotiq_description/meshes/collision/left_inner_knuckle.stl</uri>
          </mesh>
        </geometry>
      </collision>
      <visual name='robotiq_85_left_inner_knuckle_link_visual'>
        <pose>0 0 0 0 0 0</pose>
        <geometry>
          <mesh>
            <scale>1 1 1</scale>
            <uri>file:///opt/ros/jazzy/share/robotiq_description/meshes/visual/left_inner_knuckle.dae</uri>
          </mesh>
        </geometry>
      </visual>
    </link>
    <joint name='robotiq_85_left_knuckle_joint' type='revolute'>
      <pose relative_to='wrist_3_link'>0.030601139999999982 8.6736173798840355e-18 0.065904519999999994 -2.4651903288156619e-32 -2.2204460492503131e-16 2.2204460492503131e-16</pose>
      <parent>wrist_3_link</parent>
      <child>robotiq_85_left_knuckle_link</child>
      <axis>
        <xyz>0 -1 0</xyz>
        <limit>
          <lower>0</lower>
          <upper>0.80000000000000004</upper>
          <effort>50</effort>
          <velocity>0.5</velocity>
        </limit>
        <dynamics>
          <spring_reference>0</spring_reference>
          <spring_stiffness>0</spring_stiffness>
        </dynamics>
      </axis>
    </joint>
    <link name='robotiq_85_left_knuckle_link'>
      <pose relative_to='robotiq_85_left_knuckle_joint'>0 0 0 0 0 0</pose>
      <inertial>
        <pose>0.029386739357586979 -0.000550523351652724 0.01110696109436298 0 0 0</pose>
        <mass>0.056451499600000003</mass>
        <inertia>
          <ixx>1.672951427632284e-05</ixx>
          <ixy>2.376180881559496e-07</ixy>
          <ixz>-5.7573775998137648e-06</ixz>
          <iyy>2.2123373744517121e-05</iyy>
          <iyz>1.6103204181075421e-07</iyz>
          <izz>1.2901330613689229e-05</izz>
        </inertia>
      </inertial>
      <collision name='robotiq_85_left_knuckle_link_collision'>
        <pose>0 0 0 0 0 0</pose>
        <geometry>
          <mesh>
            <scale>1 1 1</scale>
            <uri>file:///opt/ros/jazzy/share/robotiq_description/meshes/collision/left_knuckle.stl</uri>
          </mesh>
        </geometry>
      </collision>
      <collision name='robotiq_85_left_knuckle_link_fixed_joint_lump__robotiq_85_left_finger_link_collision_1'>
        <pose>0.031526159999999998 0 -0.0037634700000000001 0 0 0</pose>
        <geometry>
          <mesh>
            <scale>1 1 1</scale>
            <uri>file:///opt/ros/jazzy/share/robotiq_description/meshes/collision/left_finger.stl</uri>
          </mesh>
        </geometry>
      </collision>
      <visual name='robotiq_85_left_knuckle_link_visual'>
        <pose>0 0 0 0 0 0</pose>
        <geometry>
          <mesh>
            <scale>1 1 1</scale>
            <uri>file:///opt/ros/jazzy/share/robotiq_description/meshes/visual/left_knuckle.dae</uri>
          </mesh>
        </geometry>
      </visual>
      <visual name='robotiq_85_left_knuckle_link_fixed_joint_lump__robotiq_85_left_finger_link_visual_1'>
        <pose>0.031526159999999998 0 -0.0037634700000000001 0 0 0</pose>
        <geometry>
          <mesh>
            <scale>1 1 1</scale>
            <uri>file:///opt/ros/jazzy/share/robotiq_description/meshes/visual/left_finger.dae</uri>
          </mesh>
        </geometry>
      </visual>
    </link>
    <joint name='robotiq_85_left_finger_tip_joint' type='revolute'>
      <pose relative_to='robotiq_85_left_knuckle_link'>0.037157500000000003 0 0.043421679999999997 0 0 0</pose>
      <parent>robotiq_85_left_knuckle_link</parent>
      <child>robotiq_85_left_finger_tip_link</child>
      <axis>
        <xyz>0 -1 0</xyz>
        <mimic joint='robotiq_85_left_knuckle_joint'>
          <multiplier>-1</multiplier>
          <offset>0</offset>
          <reference>0</reference>
        </mimic>
        <limit>
          <lower>-inf</lower>
          <upper>inf</upper>
        </limit>
        <dynamics>
          <spring_reference>0</spring_reference>
          <spring_stiffness>0</spring_stiffness>
        </dynamics>
      </axis>
    </joint>
    <link name='robotiq_85_left_finger_tip_link'>
      <pose relative_to='robotiq_85_left_finger_tip_joint'>0 0 0 0 0 0</pose>
      <inertial>
        <pose>-0.01456706 -0.00080000000000000004 0.016497009999999999 0 0 0</pose>
        <mass>0.04268588744</mass>
        <inertia>
          <ixx>1.0481519999999999e-05</ixx>
          <ixy>0</ixy>
          <ixz>3.5232e-06</ixz>
          <iyy>1.197888e-05</iyy>
          <iyz>0</iyz>
          <izz>4.2278399999999998e-06</izz>
        </inertia>
      </inertial>
      <collision name='robotiq_85_left_finger_tip_link_collision'>
        <pose>0 0 0 0 0 0</pose>
        <geometry>
          <mesh>
            <scale>1 1 1</scale>
            <uri>file:///opt/ros/jazzy/share/robotiq_description/meshes/collision/left_finger_tip.stl</uri>
          </mesh>
        </geometry>
      </collision>
      <visual name='robotiq_85_left_finger_tip_link_visual'>
        <pose>0 0 0 0 0 0</pose>
        <geometry>
          <mesh>
            <scale>1 1 1</scale>
            <uri>file:///opt/ros/jazzy/share/robotiq_description/meshes/visual/left_finger_tip.dae</uri>
          </mesh>
        </geometry>
      </visual>
    </link>
    <joint name='robotiq_85_right_inner_knuckle_joint' type='revolute'>
      <pose relative_to='wrist_3_link'>-0.012699999999999999 0 0.072419999999999984 -2.4651903288156619e-32 -2.2204460492503131e-16 2.2204460492503131e-16</pose>
      <parent>wrist_3_link</parent>
      <child>robotiq_85_right_inner_knuckle_link</child>
      <axis>
        <xyz>0 -1 0</xyz>
        <mimic joint='robotiq_85_left_knuckle_joint'>
          <multiplier>-1</multiplier>
          <offset>0</offset>
          <reference>0</reference>
        </mimic>
        <limit>
          <lower>-inf</lower>
          <upper>inf</upper>
        </limit>
        <dynamics>
          <spring_reference>0</spring_reference>
          <spring_stiffness>0</spring_stiffness>
        </dynamics>
      </axis>
    </joint>
    <link name='robotiq_85_right_inner_knuckle_link'>
      <pose relative_to='robotiq_85_right_inner_knuckle_joint'>0 0 0 0 0 0</pose>
      <inertial>
        <pose>-0.019268239999999999 5.0009999999999997e-05 0.02222178 0 0 0</pose>
        <mass>0.029693764479999999</mass>
        <inertia>
          <ixx>9.4245600000000001e-06</ixx>
          <ixy>0</ixy>
          <ixz>3.9635999999999996e-06</ixz>
          <iyy>8.69056e-06</iyy>
          <iyz>0</iyz>
          <izz>8.3382400000000003e-06</izz>
        </inertia>
      </inertial>
      <collision name='robotiq_85_right_inner_knuckle_link_collision'>
        <pose>0 0 0 0 0 0</pose>
        <geometry>
          <mesh>
            <scale>1 1 1</scale>
            <uri>file:///opt/ros/jazzy/share/robotiq_description/meshes/collision/right_inner_knuckle.stl</uri>
          </mesh>
        </geometry>
      </collision>
      <visual name='robotiq_85_right_inner_knuckle_link_visual'>
        <pose>0 0 0 0 0 0</pose>
        <geometry>
          <mesh>
            <scale>1 1 1</scale>
            <uri>file:///opt/ros/jazzy/share/robotiq_description/meshes/visual/right_inner_knuckle.dae</uri>
          </mesh>
        </geometry>
      </visual>
    </link>
    <joint name='robotiq_85_right_knuckle_joint' type='revolute'>
      <pose relative_to='wrist_3_link'>-0.03060114000000002 -1.387778780781446e-17 0.065904519999999994 -2.4651903288156619e-32 -2.2204460492503131e-16 2.2204460492503131e-16</pose>
      <parent>wrist_3_link</parent>
      <child>robotiq_85_right_knuckle_link</child>
      <axis>
        <xyz>0 -1 0</xyz>
        <mimic joint='robotiq_85_left_knuckle_joint'>
          <multiplier>-1</multiplier>
          <offset>0</offset>
          <reference>0</reference>
        </mimic>
        <limit>
          <lower>-0.80000000000000004</lower>
          <upper>0</upper>
          <effort>50</effort>
          <velocity>0.5</velocity>
        </limit>
        <dynamics>
          <spring_reference>0</spring_reference>
          <spring_stiffness>0</spring_stiffness>
        </dynamics>
      </axis>
    </joint>
    <link name='robotiq_85_right_knuckle_link'>
      <pose relative_to='robotiq_85_right_knuckle_joint'>0 0 0 0 0 0</pose>
      <inertial>
        <pose>-0.029386739357586979 4.4887161538121481e-05 0.01110696109436298 0 0 0</pose>
        <mass>0.056451499600000003</mass>
        <inertia>
          <ixx>1.67196201740057e-05</ixx>
          <ixy>-4.9109219643319929e-08</ixy>
          <ixz>5.7573775998137648e-06</ixz>
          <iyy>2.2123373744517121e-05</iyy>
          <iyz>3.3280959258061408e-08</iyz>
          <izz>1.289143651137209e-05</izz>
        </inertia>
      </inertial>
      <collision name='robotiq_85_right_knuckle_link_collision'>
        <pose>0 0 0 0 0 0</pose>
        <geometry>
          <mesh>
            <scale>1 1 1</scale>
            <uri>file:///opt/ros/jazzy/share/robotiq_description/meshes/collision/right_knuckle.stl</uri>
          </mesh>
        </geometry>
      </collision>
      <collision name='robotiq_85_right_knuckle_link_fixed_joint_lump__robotiq_85_right_finger_link_collision_1'>
        <pose>-0.031526159999999998 0 -0.0037634700000000001 0 0 0</pose>
        <geometry>
          <mesh>
            <scale>1 1 1</scale>
            <uri>file:///opt/ros/jazzy/share/robotiq_description/meshes/collision/right_finger.stl</uri>
          </mesh>
        </geometry>
      </collision>
      <visual name='robotiq_85_right_knuckle_link_visual'>
        <pose>0 0 0 0 0 0</pose>
        <geometry>
          <mesh>
            <scale>1 1 1</scale>
            <uri>file:///opt/ros/jazzy/share/robotiq_description/meshes/visual/right_knuckle.dae</uri>
          </mesh>
        </geometry>
      </visual>
      <visual name='robotiq_85_right_knuckle_link_fixed_joint_lump__robotiq_85_right_finger_link_visual_1'>
        <pose>-0.031526159999999998 0 -0.0037634700000000001 0 0 0</pose>
        <geometry>
          <mesh>
            <scale>1 1 1</scale>
            <uri>file:///opt/ros/jazzy/share/robotiq_description/meshes/visual/right_finger.dae</uri>
          </mesh>
        </geometry>
      </visual>
    </link>
    <joint name='robotiq_85_right_finger_tip_joint' type='revolute'>
      <pose relative_to='robotiq_85_right_knuckle_link'>-0.037157500000000003 0 0.043421679999999997 0 0 0</pose>
      <parent>robotiq_85_right_knuckle_link</parent>
      <child>robotiq_85_right_finger_tip_link</child>
      <axis>
        <xyz>0 -1 0</xyz>
        <mimic joint='robotiq_85_left_knuckle_joint'>
          <multiplier>1</multiplier>
          <offset>0</offset>
          <reference>0</reference>
        </mimic>
        <limit>
          <lower>-inf</lower>
          <upper>inf</upper>
        </limit>
        <dynamics>
          <spring_reference>0</spring_reference>
          <spring_stiffness>0</spring_stiffness>
        </dynamics>
      </axis>
    </joint>
    <link name='robotiq_85_right_finger_tip_link'>
      <pose relative_to='robotiq_85_right_finger_tip_joint'>0 0 0 0 0 0</pose>
      <inertial>
        <pose>0.01456706 5.0000000000000002e-05 0.016497009999999999 0 0 0</pose>
        <mass>0.04268588744</mass>
        <inertia>
          <ixx>1.0481519999999999e-05</ixx>
          <ixy>0</ixy>
          <ixz>-3.5232e-06</ixz>
          <iyy>1.197888e-05</iyy>
          <iyz>0</iyz>
          <izz>4.2278399999999998e-06</izz>
        </inertia>
      </inertial>
      <collision name='robotiq_85_right_finger_tip_link_collision'>
        <pose>0 0 0 0 0 0</pose>
        <geometry>
          <mesh>
            <scale>1 1 1</scale>
            <uri>file:///opt/ros/jazzy/share/robotiq_description/meshes/collision/right_finger_tip.stl</uri>
          </mesh>
        </geometry>
      </collision>
      <visual name='robotiq_85_right_finger_tip_link_visual'>
        <pose>0 0 0 0 0 0</pose>
        <geometry>
          <mesh>
            <scale>1 1 1</scale>
            <uri>file:///opt/ros/jazzy/share/robotiq_description/meshes/visual/right_finger_tip.dae</uri>
          </mesh>
        </geometry>
      </visual>
    </link>
    <frame name='base_link-base_fixed_joint' attached_to='base_link'>
      <pose>0 0 0 0 0 3.1415926535897931</pose>
    </frame>
    <frame name='base' attached_to='base_link-base_fixed_joint'>
      <pose>0 0 0 0 0 0</pose>
    </frame>
    <frame name='base_link-base_link_inertia' attached_to='base_link'>
      <pose>0 0 0 0 0 3.1415926535897931</pose>
    </frame>
    <frame name='base_link_inertia' attached_to='base_link-base_link_inertia'>
      <pose>0 0 0 0 0 0</pose>
    </frame>
    <frame name='robotiq_85_base_joint' attached_to='gripper_mount_link'>
      <pose>0 0 0 0 0 0</pose>
    </frame>
    <frame name='robotiq_85_base_link' attached_to='robotiq_85_base_joint'>
      <pose>0 0 0 0 0 0</pose>
    </frame>
    <frame name='robotiq_85_left_finger_joint' attached_to='robotiq_85_left_knuckle_link'>
      <pose>0.031526159999999998 0 -0.0037634700000000001 0 0 0</pose>
    </frame>
    <frame name='robotiq_85_left_finger_link' attached_to='robotiq_85_left_finger_joint'>
      <pose>0 0 0 0 0 0</pose>
    </frame>
    <frame name='robotiq_85_right_finger_joint' attached_to='robotiq_85_right_knuckle_link'>
      <pose>-0.031526159999999998 0 -0.0037634700000000001 0 0 0</pose>
    </frame>
    <frame name='robotiq_85_right_finger_link' attached_to='robotiq_85_right_finger_joint'>
      <pose>0 0 0 0 0 0</pose>
    </frame>
    <frame name='gripper_side_joint' attached_to='ur_to_robotiq_link'>
      <pose>0 0 0.010999999999999999 0 0 0</pose>
    </frame>
    <frame name='gripper_mount_link' attached_to='gripper_side_joint'>
      <pose>0 0 0 0 0 0</pose>
    </frame>
    <frame name='ur_to_robotiq_joint' attached_to='tool0'>
      <pose>0 0 0 0 0 0</pose>
    </frame>
    <frame name='ur_to_robotiq_link' attached_to='ur_to_robotiq_joint'>
      <pose>0 0 0 0 0 0</pose>
    </frame>
    <frame name='flange-tool0' attached_to='flange'>
      <pose>0 0 0 1.5707963267948959 -5.5511151231257827e-17 1.5707963267948959</pose>
    </frame>
    <frame name='tool0' attached_to='flange-tool0'>
      <pose>0 0 0 0 0 0</pose>
    </frame>
    <frame name='wrist_3-flange' attached_to='wrist_3_link'>
      <pose>0 0 0 -1.5707963267948957 -1.5707963267948966 0</pose>
    </frame>
    <frame name='flange' attached_to='wrist_3-flange'>
      <pose>0 0 0 0 0 0</pose>
    </frame>
    <frame name='wrist_3_link-ft_frame' attached_to='wrist_3_link'>
      <pose>0 0 0 3.1415926535897931 0 0</pose>
    </frame>
    <frame name='ft_frame' attached_to='wrist_3_link-ft_frame'>
      <pose>0 0 0 0 0 0</pose>
    </frame>
  </model>
</sdf>
