<?xml version="1.0" ?>
<!-- =================================================================================== -->
<!-- |    This document was autogenerated by xacro from diff_drive.urdf.xacro          | -->
<!-- |    EDITING THIS FILE BY HAND IS NOT RECOMMENDED                                 | -->
<!-- =================================================================================== -->
<!-- Reference: https://github.com/lucasmazzetto/gazebo_differential_drive_robot -->
<robot name="diff_drive">
  <!-- Chasis cool-blue -->
  <material name="chasis-material">
    <color rgba="0.27450980392156865 0.5098039215686274 0.7058823529411765 1.0"/>
    <ambient>0.1 0.2 0.3 1</ambient>
    <!-- Soft blue under ambient light -->
    <diffuse>0.3 0.5 0.7 1</diffuse>
    <!-- Calm, mid-tone blue under direct lighting -->
    <specular>0.2 0.3 0.4 1</specular>
    <!-- Slight shine with blue undertones -->
    <emissive>0.0 0.0 0.0 1</emissive>
    <!-- No glow -->
  </material>
  <!-- Right Wheel cool-teal -->
  <material name="right-wheel-material">
    <color rgba="0.0 0.5019607843137255 0.5019607843137255 1.0"/>
    <ambient>0.1 0.3 0.3 1</ambient>
    <!-- Muted teal under ambient light -->
    <diffuse>0.0 0.5 0.5 1</diffuse>
    <!-- Teal under direct lighting -->
    <specular>0.1 0.3 0.3 1</specular>
    <!-- Slight shine with a cool tint -->
    <emissive>0.0 0.0 0.0 1</emissive>
    <!-- No glow -->
  </material>
  <!-- Left Wheel deep-purple -->
  <material name="left-wheel-material">
    <color rgba="0.3137254901960784 0.0 0.5019607843137255 1.0"/>
    <ambient>0.2 0.0 0.2 1</ambient>
    <!-- Soft deep purple under ambient light -->
    <diffuse>0.5 0.0 0.6 1</diffuse>
    <!-- Deep purple under direct lighting -->
    <specular>0.3 0.0 0.4 1</specular>
    <!-- Glossy with purple tint -->
    <emissive>0.0 0.0 0.0 1</emissive>
    <!-- No glow -->
  </material>
  <!-- Caster Wheel cool-green -->
  <material name="caster-wheel-material">
    <color rgba="0.19607843137254902 0.803921568627451 0.19607843137254902 1.0"/>
    <ambient>0.1 0.3 0.1 1</ambient>
    <!-- Muted lime green under ambient light -->
    <diffuse>0.2 0.8 0.2 1</diffuse>
    <!-- Bright green under direct lighting -->
    <specular>0.2 0.4 0.2 1</specular>
    <!-- Slight shine with a green tint -->
    <emissive>0.0 0.0 0.0 1</emissive>
    <!-- No glow -->
  </material>
  <!-- LIDAR laser-red -->
  <material name="lidar-material">
    <color rgba="0.7843137254901961 0.0 0.0 1.0"/>
    <ambient>0.2 0.0 0.0 1</ambient>
    <!-- Dim red under ambient light -->
    <diffuse>1.0 0.0 0.0 1</diffuse>
    <!-- Bright red under direct lighting -->
    <specular>0.3 0.0 0.0 1</specular>
    <!-- Glossy red -->
    <emissive>0.3 0.0 0.0 1</emissive>
    <!-- Glowing red (representing laser-like effect) -->
  </material>
  <!-- Body Link -->
  <!-- <link name="${tf_prefix}odom" /> -->
  <link name="diff_drive/base_link">
    <visual>
      <origin rpy="0.0 0.0 0.0" xyz="0.0 0.0 0.0"/>
      <geometry>
        <box size="0.4 0.25 0.1"/>
      </geometry>
      <material name="chasis-material"/>
    </visual>
    <collision>
      <origin rpy="0.0 0.0 0.0" xyz="0.0 0.0 0.0"/>
      <geometry>
        <box size="0.4 0.25 0.1"/>
      </geometry>
    </collision>
    <inertial>
      <mass value="10"/>
      <inertia ixx="0.47427083333333336" ixy="0.0" ixz="0.0" iyy="1.1120833333333335" iyz="0" izz="1.4555208333333334"/>
      <origin rpy="0 0 0" xyz="0 0 0"/>
    </inertial>
  </link>
  <!-- Left Wheel -->
  <link name="diff_drive/left_wheel">
    <visual>
      <origin rpy="1.570795 0.0 0.0" xyz="0.0 0.0 0.0"/>
      <geometry>
        <cylinder length="0.05" radius="0.1"/>
      </geometry>
      <material name="left-wheel-material"/>
    </visual>
    <collision>
      <origin rpy="1.570795 0.0 0.0" xyz="0.0 0.0 0.0"/>
      <geometry>
        <cylinder length="0.05" radius="0.1"/>
      </geometry>
      <surface>
        <friction>
          <ode>
            <mu>1</mu>
            <mu2>1</mu2>
            <slip1>0.035</slip1>
            <slip2>0</slip2>
            <fdir1>0 0 1</fdir1>
          </ode>
          <bullet>
            <friction>1</friction>
            <friction2>1</friction2>
            <rolling_friction>0.1</rolling_friction>
          </bullet>
        </friction>
      </surface>
    </collision>
    <inertial>
      <mass value="2"/>
      <inertia ixx="0.0038288160421875023" ixy="0.0" ixz="0.0" iyy="0.0038288160421875023" iyz="0" izz="0.007068583462500003"/>
      <origin rpy="1.570795 0.0 0.0" xyz="0.0 0.0 0.0"/>
    </inertial>
  </link>
  <!-- Right Wheel -->
  <link name="diff_drive/right_wheel">
    <visual>
      <origin rpy="1.570795 0.0 0.0" xyz="0.0 0.0 0.0"/>
      <geometry>
        <cylinder length="0.05" radius="0.1"/>
      </geometry>
      <material name="right-wheel-material"/>
    </visual>
    <collision>
      <origin rpy="1.570795 0.0 0.0" xyz="0.0 0.0 0.0"/>
      <geometry>
        <cylinder length="0.05" radius="0.1"/>
      </geometry>
      <surface>
        <friction>
          <ode>
            <mu>1</mu>
            <mu2>1</mu2>
            <slip1>0.035</slip1>
            <slip2>0</slip2>
            <fdir1>0 0 1</fdir1>
          </ode>
          <bullet>
            <friction>1</friction>
            <friction2>1</friction2>
            <rolling_friction>0.1</rolling_friction>
          </bullet>
        </friction>
      </surface>
    </collision>
    <inertial>
      <mass value="2"/>
      <inertia ixx="0.0038288160421875023" ixy="0.0" ixz="0.0" iyy="0.0038288160421875023" iyz="0" izz="0.007068583462500003"/>
      <origin rpy="1.570795 0.0 0.0" xyz="0.0 0.0 0.0"/>
    </inertial>
  </link>
  <!-- Caster Wheel -->
  <link name="diff_drive/caster">
    <visual>
      <origin rpy="0.0 0.0 0.0" xyz="0.0 0.0 0.0"/>
      <geometry>
        <sphere radius="0.05"/>
      </geometry>
      <material name="caster-wheel-material"/>
    </visual>
    <collision>
      <origin rpy="0.0 0.0 0.0" xyz="0.0 0.0 0.0"/>
      <geometry>
        <sphere radius="0.05"/>
      </geometry>
    </collision>
    <inertial>
      <mass value="0.5"/>
      <inertia ixx="5.235987750000002e-08" ixy="0.0" ixz="0.0" iyy="5.235987750000002e-08" iyz="0" izz="5.235987750000002e-08"/>
      <origin rpy="0 0 0" xyz="0 0 0"/>
    </inertial>
  </link>
  <!-- LIDAR -->
  <link name="diff_drive/lidar">
    <inertial>
      <mass value="0.1"/>
      <inertia ixx="0.0000027" ixy="0.0" ixz="0.0" iyy="0.0000027" iyz="0" izz="0.0000027"/>
      <origin rpy="0 0 0" xyz="0 0 0"/>
    </inertial>
    <visual>
      <origin rpy="0.0 0.0 0.0" xyz="0.0 0.0 0.0"/>
      <geometry>
        <cylinder length="0.04" radius="0.01"/>
      </geometry>
      <material name="lidar-material"/>
    </visual>
    <collision>
      <geometry>
        <cylinder length="0.04" radius="0.01"/>
      </geometry>
    </collision>
  </link>
  <!-- Joints -->
  <!-- Floor Joint -->
  <!-- <joint name="${tf_prefix}floor_fixed_joint" type="fixed">
            <origin xyz="0 0 ${wheel_radius+body_height/2}" rpy="0 0 0"/>
            <parent link="${tf_prefix}odom"/>
            <child link="${tf_prefix}base_link"/>
        </joint> -->
  <!-- Left Wheel Joint -->
  <joint name="diff_drive/left_wheel_joint" type="continuous">
    <origin rpy="0 0 0" xyz="-0.1 0.15 -0.05"/>
    <parent link="diff_drive/base_link"/>
    <child link="diff_drive/left_wheel"/>
    <axis xyz="0 1 0"/>
    <limit effort="100" velocity="10.0"/>
    <dynamics damping="0.1" friction="0.1"/>
  </joint>
  <!-- Right Wheel Joint -->
  <joint name="diff_drive/right_wheel_joint" type="continuous">
    <origin rpy="0 0 0" xyz="-0.1 -0.15 -0.05"/>
    <parent link="diff_drive/base_link"/>
    <child link="diff_drive/right_wheel"/>
    <axis xyz="0 1 0"/>
    <limit effort="100" velocity="10.0"/>
    <dynamics damping="0.1" friction="0.1"/>
  </joint>
  <!-- Caster Wheel Joint (fixed) or Ball?!? -->
  <joint name="diff_drive/caster_joint" type="fixed">
    <origin rpy="0 0 0" xyz="0.15000000000000002 0 -0.1"/>
    <parent link="diff_drive/base_link"/>
    <child link="diff_drive/caster"/>
  </joint>
  <!-- Lidar Joint (fixed) -->
  <joint name="diff_drive/lidar_joint" type="fixed">
    <origin rpy="0 0 0" xyz="0.15000000000000002 0 0.07"/>
    <!-- Using the same position as the caster wheel but above it! -->
    <parent link="diff_drive/base_link"/>
    <child link="diff_drive/lidar"/>
  </joint>
  <!-- ros_control plugin -->
  <!-- Gazebo Parameters -->
  <gazebo reference="diff_drive/base_link">
    <mu1>1.0</mu1>
    <mu2>1.0</mu2>
  </gazebo>
  <gazebo reference="diff_drive/right_wheel">
    <mu1>1.0</mu1>
    <mu2>1.0</mu2>
  </gazebo>
  <gazebo reference="diff_drive/left_wheel">
    <mu1>1.0</mu1>
    <mu2>1.0</mu2>
  </gazebo>
  <gazebo reference="diff_drive/caster">
    <mu1>0.000001</mu1>
    <mu2>0.000001</mu2>
  </gazebo>
  <gazebo reference="diff_drive/lidar">
    <mu1>1.0</mu1>
    <mu2>1.0</mu2>
    <sensor name="lidar_sensor" type="gpu_lidar">
      <pose>0 0 0 0 0 0</pose>
      <topic>/lidar</topic>
      <update_rate>10</update_rate>
      <frame_id>diff_drive/lidar</frame_id>
      <lidar>
        <scan>
          <horizontal>
            <samples>36</samples>
            <resolution>1</resolution>
            <min_angle>-3.14159</min_angle>
            <max_angle>3.14159</max_angle>
          </horizontal>
        </scan>
        <range>
          <min>0.1</min>
          <max>30.0</max>
          <resolution>0.01</resolution>
        </range>
        <noise>
          <type>gaussian</type>
          <mean>0.0</mean>
          <stddev>0.01</stddev>
        </noise>
      </lidar>
      <always_on>1</always_on>
      <visualize>true</visualize>
    </sensor>
  </gazebo>
  <gazebo>
    <plugin filename="gz-sim-diff-drive-system" name="gz::sim::systems::DiffDrive">
      <left_joint>diff_drive/left_wheel_joint</left_joint>
      <right_joint>diff_drive/right_wheel_joint</right_joint>
      <wheel_separation>0.3</wheel_separation>
      <wheel_radius>0.1</wheel_radius>
      <odom_publish_frequency>30</odom_publish_frequency>
      <max_wheel_torque>2.0</max_wheel_torque>
      <max_wheel_acceleration>0.75</max_wheel_acceleration>
      <topic>/cmd_vel</topic>
      <odom_topic>/odom</odom_topic>
      <frame_id>odom</frame_id>
      <child_frame_id>diff_drive/base_link</child_frame_id>
      <tf_topic>/tf</tf_topic>
      <publish_odom_tf>true</publish_odom_tf>
    </plugin>
    <plugin filename="gz-sim-joint-state-publisher-system" name="gz::sim::systems::JointStatePublisher">
      <topic>/joint_states</topic>
      <publish_tf>false</publish_tf>
    </plugin>
    <plugin filename="gz-sim-pose-publisher-system" name="gz::sim::systems::PosePublisher">
      <publish_link_pose>true</publish_link_pose>
      <publish_sensor_pose>false</publish_sensor_pose>
      <publish_collision_pose>false</publish_collision_pose>
      <publish_visual_pose>false</publish_visual_pose>
      <publish_nested_model_pose>true</publish_nested_model_pose>
      <use_pose_vector_msg>true</use_pose_vector_msg>
      <static_publisher>false</static_publisher>
      <update_frequency>30</update_frequency>
      <topic>/model/diff_drive/pose</topic>
    </plugin>
    <plugin filename="gz-sim-sensors-system" name="gz::sim::systems::Sensors">
      <render_engine>ogre2</render_engine>
    </plugin>
  </gazebo>
  <ros2_control name="diff_drive_ros2_control" type="system">
    <hardware>
      <!-- Use Gazebo plugin for simulation -->
      <plugin>gz_ros2_control/GazeboSimSystem</plugin>
    </hardware>
    <joint name="diff_drive/left_wheel_joint">
      <command_interface name="position"/>
      <state_interface name="position">
        <param name="initial_value">0</param>
      </state_interface>
      <state_interface name="velocity"/>
    </joint>
    <joint name="diff_drive/right_wheel_joint">
      <command_interface name="position"/>
      <state_interface name="position">
        <param name="initial_value">0</param>
      </state_interface>
      <state_interface name="velocity"/>
    </joint>
  </ros2_control>
</robot>
