<?xml version="1.0" ?>
<!-- =================================================================================== -->
<!-- |    This document was autogenerated by xacro from dual_devol.urdf.xacro          | -->
<!-- |    EDITING THIS FILE BY HAND IS NOT RECOMMENDED                                 | -->
<!-- =================================================================================== -->
<!-- Reference: https://github.com/lucasmazzetto/gazebo_differential_drive_robot -->
<robot name="dual_devol">
  <material name="dark-blue-metal">
    <color rgba="0.0 0.0 0.4 1.0"/>
  </material>
  <material name="dark-purple-metal">
    <color rgba="0.4 0.0 0.4 1.0"/>
  </material>
  <material name="metallic-green">
    <color rgba="0.0 0.5019607843137255 0.0 1.0"/>
  </material>
  <!--
    Base UR robot series xacro macro.

    NOTE this is NOT a URDF. It cannot directly be loaded by consumers
    expecting a flattened '.urdf' file. See the top-level '.xacro' for that
    (but note that .xacro must still be processed by the xacro command).

    This file models the base kinematic chain of a UR robot, which then gets
    parameterised by various configuration files to convert it into a UR3(e),
    UR5(e), UR10(e) or UR16e.

    NOTE the default kinematic parameters (i.e., link lengths, frame locations,
    offsets, etc) do not correspond to any particular robot. They are defaults
    only. There WILL be non-zero offsets between the Forward Kinematics results
    in TF (i.e., robot_state_publisher) and the values reported by the Teach
    Pendant.

    For accurate (and robot-specific) transforms, the 'kinematics_parameters_file'
    parameter MUST point to a .yaml file containing the appropriate values for
    the targeted robot.

    If using the UniversalRobots/Universal_Robots_ROS_Driver, follow the steps
    described in the readme of that repository to extract the kinematic
    calibration from the controller and generate the required .yaml file.

    Main author of the migration to yaml configs Ludovic Delval.

    Contributors to previous versions (in no particular order)

     - Denis Stogl
     - Lovro Ivanov
     - Felix Messmer
     - Kelsey Hawkins
     - Wim Meeussen
     - Shaun Edwards
     - Nadia Hammoudeh Garcia
     - Dave Hershberger
     - G. vd. Hoorn
     - Philip Long
     - Dave Coleman
     - Miguel Prada
     - Mathias Luedtke
     - Marcel Schnirring
     - Felix von Drigalski
     - Felix Exner
     - Jimmy Da Silva
     - Ajit Krisshna N L
     - Muhammad Asif Rana
  -->
  <material name="aluminum">
    <color rgba="0.5 0.5 0.5 1"/>
  </material>
  <material name="plastic">
    <color rgba="0.1 0.1 0.1 1"/>
  </material>
  <link name="empty"/>
  <!-- Body Link -->
  <link name="artemis_body_link">
    <visual>
      <origin rpy="0.0 0.0 0.0" xyz="0.0 0.0 0.0"/>
      <geometry>
        <box size="0.5 0.3 0.1"/>
      </geometry>
      <material name="dark-blue-metal"/>
    </visual>
    <collision>
      <origin rpy="0.0 0.0 0.0" xyz="0.0 0.0 0.0"/>
      <geometry>
        <box size="0.5 0.3 0.1"/>
      </geometry>
    </collision>
    <inertial>
      <mass value="10"/>
      <inertia ixx="0.9812500000000001" ixy="0.0" ixz="0.0" iyy="2.55125" iyz="0" izz="3.3362499999999997"/>
      <origin rpy="0 0 0" xyz="0 0 0"/>
    </inertial>
  </link>
  <joint name="artemis_base_to_body" type="fixed">
    <parent link="empty"/>
    <child link="artemis_body_link"/>
    <origin rpy="0 0 0" xyz="0 0 0.15"/>
  </joint>
  <!-- Left Wheel -->
  <link name="artemis_left_wheel_link">
    <visual>
      <origin rpy="1.570795 0.0 0.0" xyz="0.0 0.0 0.0"/>
      <geometry>
        <cylinder length="0.05" radius="0.1"/>
      </geometry>
      <material name="dark-purple-metal"/>
    </visual>
    <collision>
      <origin rpy="1.570795 0.0 0.0" xyz="0.0 0.0 0.0"/>
      <geometry>
        <cylinder length="0.05" radius="0.1"/>
      </geometry>
      <surface>
        <friction>
          <ode>
            <mu>1</mu>
            <mu2>1</mu2>
            <slip1>0.035</slip1>
            <slip2>0</slip2>
            <fdir1>0 0 1</fdir1>
          </ode>
          <bullet>
            <friction>1</friction>
            <friction2>1</friction2>
            <rolling_friction>0.1</rolling_friction>
          </bullet>
        </friction>
      </surface>
    </collision>
    <inertial>
      <mass value="2"/>
      <inertia ixx="0.0038288160421875023" ixy="0.0" ixz="0.0" iyy="0.0038288160421875023" iyz="0" izz="0.007068583462500003"/>
      <origin rpy="1.570795 0.0 0.0" xyz="0.0 0.0 0.0"/>
    </inertial>
  </link>
  <!-- Right Wheel -->
  <link name="artemis_right_wheel_link">
    <visual>
      <origin rpy="1.570795 0.0 0.0" xyz="0.0 0.0 0.0"/>
      <geometry>
        <cylinder length="0.05" radius="0.1"/>
      </geometry>
      <material name="dark-purple-metal"/>
    </visual>
    <collision>
      <origin rpy="1.570795 0.0 0.0" xyz="0.0 0.0 0.0"/>
      <geometry>
        <cylinder length="0.05" radius="0.1"/>
      </geometry>
      <surface>
        <friction>
          <ode>
            <mu>1</mu>
            <mu2>1</mu2>
            <slip1>0.035</slip1>
            <slip2>0</slip2>
            <fdir1>0 0 1</fdir1>
          </ode>
          <bullet>
            <friction>1</friction>
            <friction2>1</friction2>
            <rolling_friction>0.1</rolling_friction>
          </bullet>
        </friction>
      </surface>
    </collision>
    <inertial>
      <mass value="2"/>
      <inertia ixx="0.0038288160421875023" ixy="0.0" ixz="0.0" iyy="0.0038288160421875023" iyz="0" izz="0.007068583462500003"/>
      <origin rpy="1.570795 0.0 0.0" xyz="0.0 0.0 0.0"/>
    </inertial>
  </link>
  <!-- Caster Wheel -->
  <link name="artemis_caster_link">
    <visual>
      <origin rpy="0.0 0.0 0.0" xyz="0.0 0.0 0.0"/>
      <geometry>
        <sphere radius="0.1"/>
      </geometry>
      <material name="metallic-green"/>
    </visual>
    <collision>
      <origin rpy="0.0 0.0 0.0" xyz="0.0 0.0 0.0"/>
      <geometry>
        <sphere radius="0.1"/>
      </geometry>
    </collision>
    <inertial>
      <mass value="0.5"/>
      <inertia ixx="1.6755160800000006e-06" ixy="0.0" ixz="0.0" iyy="1.6755160800000006e-06" iyz="0" izz="1.6755160800000006e-06"/>
      <origin rpy="0 0 0" xyz="0 0 0"/>
    </inertial>
  </link>
  <!-- Joints -->
  <!-- Left Wheel Joint -->
  <joint name="artemis_left_wheel_joint" type="continuous">
    <origin rpy="0 0 0" xyz="-0.15 0.175 -0.05"/>
    <parent link="artemis_body_link"/>
    <child link="artemis_left_wheel_link"/>
    <axis xyz="0 1 0"/>
    <limit effort="100" velocity="10.0"/>
    <dynamics damping="0.1" friction="0.1"/>
  </joint>
  <!-- Right Wheel Joint -->
  <joint name="artemis_right_wheel_joint" type="continuous">
    <origin rpy="0 0 0" xyz="-0.15 -0.175 -0.05"/>
    <parent link="artemis_body_link"/>
    <child link="artemis_right_wheel_link"/>
    <axis xyz="0 1 0"/>
    <limit effort="100" velocity="10.0"/>
    <dynamics damping="0.1" friction="0.1"/>
  </joint>
  <!-- Caster Wheel Joint (fixed) -->
  <joint name="artemis_caster_joint" type="fixed">
    <origin rpy="0 0 0" xyz="0.15 0 -0.05"/>
    <parent link="artemis_body_link"/>
    <child link="artemis_caster_link"/>
  </joint>
  <!-- links -  main serial chain -->
  <!-- base_link serves as the root of the robot's kinematic tree. It follows REP-103
        conventions (i.e., X+ forward, Y+ left, Z+ up).
        Since some kinematic solvers forbid having inertia values attached to a root link, we've
        added the base_link_inertia link that carries the visual, collision and inertia
        information.
    -->
  <link name="artemis_base_link"/>
  <link name="artemis_base_link_inertia">
    <visual>
      <origin rpy="0 0 3.141592653589793" xyz="0 0 0"/>
      <geometry>
        <mesh filename="file:///opt/ros/jazzy/share/ur_description/meshes/ur3/visual/base.dae"/>
      </geometry>
    </visual>
    <collision>
      <origin rpy="0 0 3.141592653589793" xyz="0 0 0"/>
      <geometry>
        <mesh filename="file:///opt/ros/jazzy/share/ur_description/meshes/ur3/collision/base.stl"/>
      </geometry>
    </collision>
    <inertial>
      <mass value="2.0"/>
      <origin rpy="0 0 0" xyz="0 0 0"/>
      <inertia ixx="0.0030531654454" ixy="0.0" ixz="0.0" iyy="0.0030531654454" iyz="0.0" izz="0.005625"/>
    </inertial>
  </link>
  <link name="artemis_shoulder_link">
    <visual>
      <origin rpy="0 0 3.141592653589793" xyz="0 0 0"/>
      <geometry>
        <mesh filename="file:///opt/ros/jazzy/share/ur_description/meshes/ur3/visual/shoulder.dae"/>
      </geometry>
    </visual>
    <collision>
      <origin rpy="0 0 3.141592653589793" xyz="0 0 0"/>
      <geometry>
        <mesh filename="file:///opt/ros/jazzy/share/ur_description/meshes/ur3/collision/shoulder.stl"/>
      </geometry>
    </collision>
    <inertial>
      <mass value="2.0"/>
      <origin rpy="0 0 0" xyz="0.0 0.0 -0.02"/>
      <inertia ixx="0.008093166666666665" ixy="0" ixz="0" iyy="0.008093166666666665" iyz="0" izz="0.005625"/>
    </inertial>
  </link>
  <link name="artemis_upper_arm_link">
    <visual>
      <origin rpy="1.5707963267948966 0 -1.5707963267948966" xyz="0 0 0.1198"/>
      <geometry>
        <mesh filename="file:///opt/ros/jazzy/share/ur_description/meshes/ur3/visual/upperarm.dae"/>
      </geometry>
    </visual>
    <collision>
      <origin rpy="1.5707963267948966 0 -1.5707963267948966" xyz="0 0 0.1198"/>
      <geometry>
        <mesh filename="file:///opt/ros/jazzy/share/ur_description/meshes/ur3/collision/upperarm.stl"/>
      </geometry>
    </collision>
    <inertial>
      <mass value="3.42"/>
      <origin rpy="0 1.570796326794897 0" xyz="-0.11365 0.0 0.1157"/>
      <inertia ixx="0.021728491912499998" ixy="0" ixz="0" iyy="0.021728491912499998" iyz="0" izz="0.00961875"/>
    </inertial>
  </link>
  <link name="artemis_forearm_link">
    <visual>
      <origin rpy="1.5707963267948966 0 -1.5707963267948966" xyz="0 0 0.0275"/>
      <geometry>
        <mesh filename="file:///opt/ros/jazzy/share/ur_description/meshes/ur3/visual/forearm.dae"/>
      </geometry>
    </visual>
    <collision>
      <origin rpy="1.5707963267948966 0 -1.5707963267948966" xyz="0 0 0.0275"/>
      <geometry>
        <mesh filename="file:///opt/ros/jazzy/share/ur_description/meshes/ur3/collision/forearm.stl"/>
      </geometry>
    </collision>
    <inertial>
      <mass value="1.26"/>
      <origin rpy="0 1.570796326794897 0" xyz="-0.16325 0.0 0.0238"/>
      <inertia ixx="0.0065468090625" ixy="0" ixz="0" iyy="0.0065468090625" iyz="0" izz="0.00354375"/>
    </inertial>
  </link>
  <link name="artemis_wrist_1_link">
    <visual>
      <origin rpy="1.5707963267948966 0 0" xyz="0 0 -0.085"/>
      <geometry>
        <mesh filename="file:///opt/ros/jazzy/share/ur_description/meshes/ur3/visual/wrist1.dae"/>
      </geometry>
    </visual>
    <collision>
      <origin rpy="1.5707963267948966 0 0" xyz="0 0 -0.085"/>
      <geometry>
        <mesh filename="file:///opt/ros/jazzy/share/ur_description/meshes/ur3/collision/wrist1.stl"/>
      </geometry>
    </collision>
    <inertial>
      <mass value="0.8"/>
      <origin rpy="0 0 0" xyz="0.0 -0.01 0.0"/>
      <inertia ixx="0.0016106414999999998" ixy="0" ixz="0" iyy="0.0016106414999999998" iyz="0" izz="0.00225"/>
    </inertial>
  </link>
  <link name="artemis_wrist_2_link">
    <visual>
      <origin rpy="0 0 0" xyz="0 0 -0.083"/>
      <geometry>
        <mesh filename="file:///opt/ros/jazzy/share/ur_description/meshes/ur3/visual/wrist2.dae"/>
      </geometry>
    </visual>
    <collision>
      <origin rpy="0 0 0" xyz="0 0 -0.083"/>
      <geometry>
        <mesh filename="file:///opt/ros/jazzy/share/ur_description/meshes/ur3/collision/wrist2.stl"/>
      </geometry>
    </collision>
    <inertial>
      <mass value="0.8"/>
      <origin rpy="0 0 0" xyz="0.0 0.01 0.0"/>
      <inertia ixx="0.0015721739999999998" ixy="0" ixz="0" iyy="0.0015721739999999998" iyz="0" izz="0.00225"/>
    </inertial>
  </link>
  <link name="artemis_wrist_3_link">
    <visual>
      <origin rpy="1.5707963267948966 0 0" xyz="0 -0.00255 -0.082"/>
      <geometry>
        <mesh filename="file:///opt/ros/jazzy/share/ur_description/meshes/ur3/visual/wrist3.dae"/>
      </geometry>
    </visual>
    <collision>
      <origin rpy="1.5707963267948966 0 0" xyz="0 -0.00255 -0.082"/>
      <geometry>
        <mesh filename="file:///opt/ros/jazzy/share/ur_description/meshes/ur3/collision/wrist3.stl"/>
      </geometry>
    </collision>
    <inertial>
      <mass value="0.35"/>
      <origin rpy="0 0 0" xyz="0.0 0.0 -0.02"/>
      <inertia ixx="0.00013626666666666665" ixy="0" ixz="0" iyy="0.00013626666666666665" iyz="0" izz="0.0001792"/>
    </inertial>
  </link>
  <!-- base_joint fixes base_link to the environment -->
  <joint name="artemis_base_joint" type="fixed">
    <origin rpy="0 0 0" xyz="0 0 0"/>
    <parent link="artemis_body_link"/>
    <child link="artemis_base_link"/>
  </joint>
  <!-- joints - main serial chain -->
  <joint name="artemis_base_link-base_link_inertia" type="fixed">
    <parent link="artemis_base_link"/>
    <child link="artemis_base_link_inertia"/>
    <!-- 'base_link' is REP-103 aligned (so X+ forward), while the internal
           frames of the robot/controller have X+ pointing backwards.
           Use the joint between 'base_link' and 'base_link_inertia' (a dummy
           link/frame) to introduce the necessary rotation over Z (of pi rad).
      -->
    <origin rpy="0 0 3.141592653589793" xyz="0 0 0"/>
  </joint>
  <joint name="artemis_shoulder_pan_joint" type="revolute">
    <parent link="artemis_base_link_inertia"/>
    <child link="artemis_shoulder_link"/>
    <origin rpy="0 0 0" xyz="0 0 0.1519"/>
    <axis xyz="0 0 1"/>
    <limit effort="56.0" lower="-6.283185307179586" upper="6.283185307179586" velocity="3.141592653589793"/>
    <dynamics damping="0" friction="0"/>
  </joint>
  <joint name="artemis_shoulder_lift_joint" type="revolute">
    <parent link="artemis_shoulder_link"/>
    <child link="artemis_upper_arm_link"/>
    <origin rpy="1.570796327 0 0" xyz="0 0 0"/>
    <axis xyz="0 0 1"/>
    <limit effort="56.0" lower="-6.283185307179586" upper="6.283185307179586" velocity="3.141592653589793"/>
    <dynamics damping="0" friction="0"/>
  </joint>
  <joint name="artemis_elbow_joint" type="revolute">
    <parent link="artemis_upper_arm_link"/>
    <child link="artemis_forearm_link"/>
    <origin rpy="0 0 0" xyz="-0.24365 0 0"/>
    <axis xyz="0 0 1"/>
    <limit effort="28.0" lower="-3.141592653589793" upper="3.141592653589793" velocity="3.141592653589793"/>
    <dynamics damping="0" friction="0"/>
  </joint>
  <joint name="artemis_wrist_1_joint" type="revolute">
    <parent link="artemis_forearm_link"/>
    <child link="artemis_wrist_1_link"/>
    <origin rpy="0 0 0" xyz="-0.21325 0 0.11235"/>
    <axis xyz="0 0 1"/>
    <limit effort="12.0" lower="-6.283185307179586" upper="6.283185307179586" velocity="6.283185307179586"/>
    <dynamics damping="0" friction="0"/>
  </joint>
  <joint name="artemis_wrist_2_joint" type="revolute">
    <parent link="artemis_wrist_1_link"/>
    <child link="artemis_wrist_2_link"/>
    <origin rpy="1.570796327 0 0" xyz="0 -0.08535 -1.750557762378351e-11"/>
    <axis xyz="0 0 1"/>
    <limit effort="12.0" lower="-6.283185307179586" upper="6.283185307179586" velocity="6.283185307179586"/>
    <dynamics damping="0" friction="0"/>
  </joint>
  <joint name="artemis_wrist_3_joint" type="continuous">
    <parent link="artemis_wrist_2_link"/>
    <child link="artemis_wrist_3_link"/>
    <origin rpy="1.570796326589793 3.141592653589793 3.141592653589793" xyz="0 0.0819 -1.679797079540562e-11"/>
    <axis xyz="0 0 1"/>
    <limit effort="12.0" velocity="6.283185307179586"/>
    <dynamics damping="0" friction="0"/>
  </joint>
  <link name="artemis_ft_frame"/>
  <joint name="artemis_wrist_3_link-ft_frame" type="fixed">
    <parent link="artemis_wrist_3_link"/>
    <child link="artemis_ft_frame"/>
    <origin rpy="3.141592653589793 0 0" xyz="0 0 0"/>
  </joint>
  <!-- ROS-Industrial 'base' frame - base_link to UR 'Base' Coordinates transform -->
  <link name="artemis_base"/>
  <joint name="artemis_base_link-base_fixed_joint" type="fixed">
    <!-- Note the rotation over Z of pi radians - as base_link is REP-103
           aligned (i.e., has X+ forward, Y+ left and Z+ up), this is needed
           to correctly align 'base' with the 'Base' coordinate system of
           the UR controller.
      -->
    <origin rpy="0 0 3.141592653589793" xyz="0 0 0"/>
    <parent link="artemis_base_link"/>
    <child link="artemis_base"/>
  </joint>
  <!-- ROS-Industrial 'flange' frame - attachment point for EEF models -->
  <link name="artemis_flange"/>
  <joint name="artemis_wrist_3-flange" type="fixed">
    <parent link="artemis_wrist_3_link"/>
    <child link="artemis_flange"/>
    <origin rpy="0 -1.5707963267948966 -1.5707963267948966" xyz="0 0 0"/>
  </joint>
  <!-- ROS-Industrial 'tool0' frame - all-zeros tool frame -->
  <link name="artemis_tool0"/>
  <joint name="artemis_flange-tool0" type="fixed">
    <!-- default toolframe - X+ left, Y+ up, Z+ front -->
    <origin rpy="1.5707963267948966 0 1.5707963267948966" xyz="0 0 0"/>
    <parent link="artemis_flange"/>
    <child link="artemis_tool0"/>
  </joint>
  <!-- ros2 control instance -->
  <joint name="artemis_ur_to_robotiq_joint" type="fixed">
    <!-- The parent link must be read from the robot model it is attached to. -->
    <parent link="artemis_tool0"/>
    <child link="artemis_ur_to_robotiq_link"/>
    <origin rpy="0 0 0.0" xyz="0 0 0"/>
  </joint>
  <link name="artemis_ur_to_robotiq_link">
    <visual>
      <origin rpy="0 0 0" xyz="0 0 0"/>
      <geometry>
        <mesh filename="file:///opt/ros/jazzy/share/robotiq_description/meshes/visual/ur_to_robotiq_adapter.dae"/>
      </geometry>
    </visual>
    <collision>
      <origin rpy="0 0 0" xyz="0 0 0"/>
      <geometry>
        <mesh filename="file:///opt/ros/jazzy/share/robotiq_description/meshes/collision/ur_to_robotiq_adapter.stl"/>
      </geometry>
    </collision>
    <inertial>
      <mass value="0.01"/>
      <origin xyz="0 0 0"/>
      <inertia ixx="0.000044" ixy="0.0" ixz="0.0" iyy="0.000027" iyz="0.0" izz="0.000027"/>
    </inertial>
  </link>
  <joint name="artemis_gripper_side_joint" type="fixed">
    <parent link="artemis_ur_to_robotiq_link"/>
    <child link="artemis_gripper_mount_link"/>
    <!-- <origin xyz="0 0 0.011" rpy="0 ${-pi/2} ${pi/2}"/> -->
    <origin rpy="0 0 0" xyz="0 0 0.011"/>
  </joint>
  <link name="artemis_gripper_mount_link"/>
  <!-- camera body, with origin at bottom screw mount -->
  <joint name="artemis__camera_joint" type="fixed">
    <origin rpy="0 -1.570795 1.570795" xyz="0 0.08 0"/>
    <parent link="artemis_gripper_mount_link"/>
    <child link="artemis__camera_bottom_screw_frame"/>
  </joint>
  <link name="artemis__camera_bottom_screw_frame"/>
  <joint name="artemis__camera_link_joint" type="fixed">
    <origin rpy="0 0 0" xyz="0.01085 0.009 0.021"/>
    <parent link="artemis__camera_bottom_screw_frame"/>
    <child link="artemis__camera_link"/>
  </joint>
  <link name="artemis__camera_link">
    <visual>
      <!-- the mesh origin is at front plate in between the two infrared camera axes -->
      <origin rpy="1.5707963267948966 0 1.5707963267948966" xyz="0.0038 -0.009 0"/>
      <geometry>
        <mesh filename="file:///opt/ros/jazzy/share/realsense2_description/meshes/d405.stl" scale="0.001 0.001 0.001"/>
      </geometry>
      <material name="aluminum"/>
    </visual>
    <collision>
      <origin rpy="0 0 0" xyz="-0.0078 -0.009 0"/>
      <geometry>
        <box size="0.023 0.042 0.042"/>
      </geometry>
    </collision>
    <inertial>
      <!-- The following are not reliable values, and should not be used for modeling -->
      <mass value="0.072"/>
      <origin xyz="0 0 0"/>
      <inertia ixx="0.003881243" ixy="0.0" ixz="0.0" iyy="0.000498940" iyz="0.0" izz="0.003879257"/>
    </inertial>
  </link>
  <!-- camera depth joints and links -->
  <joint name="artemis__camera_depth_joint" type="fixed">
    <origin rpy="0 0 0" xyz="0 0 0"/>
    <parent link="artemis__camera_link"/>
    <child link="artemis__camera_depth_frame"/>
  </joint>
  <link name="artemis__camera_depth_frame"/>
  <joint name="artemis__camera_depth_optical_joint" type="fixed">
    <origin rpy="-1.5707963267948966 0 -1.5707963267948966" xyz="0 0 0"/>
    <parent link="artemis__camera_depth_frame"/>
    <child link="artemis__camera_depth_optical_frame"/>
  </joint>
  <link name="artemis__camera_depth_optical_frame"/>
  <!-- camera left IR joints and links -->
  <joint name="artemis__camera_infra1_joint" type="fixed">
    <origin rpy="0 0 0" xyz="0 0.0 0"/>
    <parent link="artemis__camera_link"/>
    <child link="artemis__camera_infra1_frame"/>
  </joint>
  <link name="artemis__camera_infra1_frame"/>
  <joint name="artemis__camera_infra1_optical_joint" type="fixed">
    <origin rpy="-1.5707963267948966 0 -1.5707963267948966" xyz="0 0 0"/>
    <parent link="artemis__camera_infra1_frame"/>
    <child link="artemis__camera_infra1_optical_frame"/>
  </joint>
  <link name="artemis__camera_infra1_optical_frame"/>
  <!-- camera right IR joints and links -->
  <joint name="artemis__camera_infra2_joint" type="fixed">
    <origin rpy="0 0 0" xyz="0 -0.018 0"/>
    <parent link="artemis__camera_link"/>
    <child link="artemis__camera_infra2_frame"/>
  </joint>
  <link name="artemis__camera_infra2_frame"/>
  <joint name="artemis__camera_infra2_optical_joint" type="fixed">
    <origin rpy="-1.5707963267948966 0 -1.5707963267948966" xyz="0 0 0"/>
    <parent link="artemis__camera_infra2_frame"/>
    <child link="artemis__camera_infra2_optical_frame"/>
  </joint>
  <link name="artemis__camera_infra2_optical_frame"/>
  <!-- camera color joints and links -->
  <joint name="artemis__camera_color_joint" type="fixed">
    <origin rpy="0 0 0" xyz="0 0.0 0"/>
    <parent link="artemis__camera_link"/>
    <child link="artemis__camera_color_frame"/>
  </joint>
  <link name="artemis__camera_color_frame"/>
  <joint name="artemis__camera_color_optical_joint" type="fixed">
    <origin rpy="-1.5707963267948966 0 -1.5707963267948966" xyz="0 0 0"/>
    <parent link="artemis__camera_color_frame"/>
    <child link="artemis__camera_color_optical_frame"/>
  </joint>
  <link name="artemis__camera_color_optical_frame"/>
  <link name="artemis_robotiq_85_base_link">
    <visual>
      <geometry>
        <mesh filename="file:///opt/ros/jazzy/share/robotiq_description/meshes/visual/robotiq_base.dae"/>
      </geometry>
    </visual>
    <collision>
      <geometry>
        <mesh filename="file:///opt/ros/jazzy/share/robotiq_description/meshes/collision/robotiq_base.stl"/>
      </geometry>
    </collision>
    <inertial>
      <origin rpy="0 0 0" xyz="0.0 2.274e-05 0.03232288"/>
      <mass value="6.6320197e-01"/>
      <inertia ixx="5.1617816e-04" ixy="2.936e-8" ixz="0.0" iyy="5.8802208e-04" iyz="-3.2296e-7" izz="3.9462776e-04"/>
    </inertial>
  </link>
  <link name="artemis_robotiq_85_left_knuckle_link">
    <visual>
      <geometry>
        <mesh filename="file:///opt/ros/jazzy/share/robotiq_description/meshes/visual/left_knuckle.dae"/>
      </geometry>
    </visual>
    <collision>
      <geometry>
        <mesh filename="file:///opt/ros/jazzy/share/robotiq_description/meshes/collision/left_knuckle.stl"/>
      </geometry>
    </collision>
    <inertial>
      <origin rpy="0 0 0" xyz="0.01213197 0.0002 -0.00058647"/>
      <mass value="1.384773208e-02"/>
      <inertia ixx="3.5232e-7" ixy="0.0" ixz="1.1744e-7" iyy="2.31944e-6" iyz="0" izz="2.23136e-6"/>
    </inertial>
  </link>
  <link name="artemis_robotiq_85_right_knuckle_link">
    <visual>
      <geometry>
        <mesh filename="file:///opt/ros/jazzy/share/robotiq_description/meshes/visual/right_knuckle.dae"/>
      </geometry>
    </visual>
    <collision>
      <geometry>
        <mesh filename="file:///opt/ros/jazzy/share/robotiq_description/meshes/collision/right_knuckle.stl"/>
      </geometry>
    </collision>
    <inertial>
      <origin rpy="0 0 0" xyz="-0.01213197 0.0002 -0.00058647"/>
      <mass value="1.384773208e-02"/>
      <inertia ixx="3.5232e-7" ixy="0.0" ixz="-1.1744e-7" iyy="2.31944e-6" iyz="0.0" izz="2.23136e-6"/>
    </inertial>
  </link>
  <link name="artemis_robotiq_85_left_finger_link">
    <visual>
      <geometry>
        <mesh filename="file:///opt/ros/jazzy/share/robotiq_description/meshes/visual/left_finger.dae"/>
      </geometry>
    </visual>
    <collision>
      <geometry>
        <mesh filename="file:///opt/ros/jazzy/share/robotiq_description/meshes/collision/left_finger.stl"/>
      </geometry>
    </collision>
    <inertial>
      <origin rpy="0 0 0" xyz="0.00346899 -0.00079447 0.01867121"/>
      <mass value="4.260376752e-02"/>
      <inertia ixx="1.385792000000000e-05" ixy="0.0" ixz="-2.17264e-06" iyy="1.183208e-05" iyz="0.0" izz="5.19672e-06"/>
    </inertial>
  </link>
  <link name="artemis_robotiq_85_right_finger_link">
    <visual>
      <geometry>
        <mesh filename="file:///opt/ros/jazzy/share/robotiq_description/meshes/visual/right_finger.dae"/>
      </geometry>
    </visual>
    <collision>
      <geometry>
        <mesh filename="file:///opt/ros/jazzy/share/robotiq_description/meshes/collision/right_finger.stl"/>
      </geometry>
    </collision>
    <inertial>
      <origin rpy="0 0 0" xyz="-0.00346899 -5.53e-06 0.01867121"/>
      <mass value="4.260376752000000e-02"/>
      <inertia ixx="1.385792e-05" ixy="0.0" ixz="2.17264e-06" iyy="1.183208e-05" iyz="0.0" izz="5.19672e-06"/>
    </inertial>
  </link>
  <link name="artemis_robotiq_85_left_inner_knuckle_link">
    <visual>
      <geometry>
        <mesh filename="file:///opt/ros/jazzy/share/robotiq_description/meshes/visual/left_inner_knuckle.dae"/>
      </geometry>
    </visual>
    <collision>
      <geometry>
        <mesh filename="file:///opt/ros/jazzy/share/robotiq_description/meshes/collision/left_inner_knuckle.stl"/>
      </geometry>
    </collision>
    <inertial>
      <origin rpy="0 0 0" xyz="0.01897699 0.00015001 0.02247101"/>
      <mass value="2.969376448e-02"/>
      <inertia ixx="9.57136e-06" ixy="0.0" ixz="-3.93424e-06" iyy="8.69056e-06" iyz="0.0" izz="8.19144e-06"/>
    </inertial>
  </link>
  <link name="artemis_robotiq_85_right_inner_knuckle_link">
    <visual>
      <geometry>
        <mesh filename="file:///opt/ros/jazzy/share/robotiq_description/meshes/visual/right_inner_knuckle.dae"/>
      </geometry>
    </visual>
    <collision>
      <geometry>
        <mesh filename="file:///opt/ros/jazzy/share/robotiq_description/meshes/collision/right_inner_knuckle.stl"/>
      </geometry>
    </collision>
    <inertial>
      <origin rpy="0 0 0" xyz="-0.01926824 5.001e-05 0.02222178"/>
      <mass value="2.969376448e-02"/>
      <inertia ixx="9.42456e-06" ixy="0.0" ixz="3.9636e-06" iyy="8.69056e-06" iyz="0.0" izz="8.33824e-06"/>
    </inertial>
  </link>
  <link name="artemis_robotiq_85_left_finger_tip_link">
    <visual>
      <geometry>
        <mesh filename="file:///opt/ros/jazzy/share/robotiq_description/meshes/visual/left_finger_tip.dae"/>
      </geometry>
    </visual>
    <collision>
      <geometry>
        <mesh filename="file:///opt/ros/jazzy/share/robotiq_description/meshes/collision/left_finger_tip.stl"/>
      </geometry>
      <surface>
        <friction>
          <ode>
            <mu1>100000.0</mu1>
            <mu2>100000.0</mu2>
          </ode>
        </friction>
        <contact>
          <ode>
            <kp>1e+5</kp>
            <kd>1</kd>
            <soft_cfm>0</soft_cfm>
            <soft_erp>0.2</soft_erp>
            <minDepth>0.002</minDepth>
            <maxVel>0</maxVel>
          </ode>
        </contact>
      </surface>
    </collision>
    <inertial>
      <origin rpy="0 0 0" xyz="-0.01456706 -0.0008 0.01649701"/>
      <mass value="4.268588744e-02"/>
      <inertia ixx="1.048152e-05" ixy="0.0" ixz="3.5232e-6" iyy="1.197888e-05" iyz="0.0" izz="4.22784e-06"/>
    </inertial>
  </link>
  <link name="artemis_robotiq_85_right_finger_tip_link">
    <visual>
      <geometry>
        <mesh filename="file:///opt/ros/jazzy/share/robotiq_description/meshes/visual/right_finger_tip.dae"/>
      </geometry>
    </visual>
    <collision>
      <geometry>
        <mesh filename="file:///opt/ros/jazzy/share/robotiq_description/meshes/collision/right_finger_tip.stl"/>
      </geometry>
      <surface>
        <friction>
          <ode>
            <mu1>100000.0</mu1>
            <mu2>100000.0</mu2>
          </ode>
        </friction>
        <contact>
          <ode>
            <kp>1e+5</kp>
            <kd>1</kd>
            <soft_cfm>0</soft_cfm>
            <soft_erp>0.2</soft_erp>
            <minDepth>0.002</minDepth>
            <maxVel>0</maxVel>
          </ode>
        </contact>
      </surface>
    </collision>
    <inertial>
      <origin rpy="0 0 0" xyz="0.01456706 5e-05 0.01649701"/>
      <mass value="4.268588744e-02"/>
      <inertia ixx="1.048152e-05" ixy="0.0" ixz="-3.5232e-06" iyy="1.197888e-05" iyz="0.0" izz="4.22784e-06"/>
    </inertial>
  </link>
  <joint name="artemis_robotiq_85_base_joint" type="fixed">
    <parent link="artemis_gripper_mount_link"/>
    <child link="artemis_robotiq_85_base_link"/>
    <origin rpy="0 0 0" xyz="0 0 0"/>
  </joint>
  <joint name="artemis_robotiq_85_left_knuckle_joint" type="revolute">
    <parent link="artemis_robotiq_85_base_link"/>
    <child link="artemis_robotiq_85_left_knuckle_link"/>
    <axis xyz="0 -1 0"/>
    <origin rpy="0 0 0" xyz="0.03060114 0.0 0.05490452"/>
    <limit effort="50" lower="0.0" upper="0.8" velocity="0.5"/>
  </joint>
  <joint name="artemis_robotiq_85_right_knuckle_joint" type="revolute">
    <parent link="artemis_robotiq_85_base_link"/>
    <child link="artemis_robotiq_85_right_knuckle_link"/>
    <axis xyz="0 -1 0"/>
    <origin rpy="0 0 0" xyz="-0.03060114 0.0 0.05490452"/>
    <limit effort="50" lower="-0.8" upper="0.0" velocity="0.5"/>
    <mimic joint="artemis_robotiq_85_left_knuckle_joint" multiplier="-1"/>
  </joint>
  <joint name="artemis_robotiq_85_left_finger_joint" type="fixed">
    <parent link="artemis_robotiq_85_left_knuckle_link"/>
    <child link="artemis_robotiq_85_left_finger_link"/>
    <origin rpy="0 0 0" xyz="0.03152616 0.0 -0.00376347"/>
  </joint>
  <joint name="artemis_robotiq_85_right_finger_joint" type="fixed">
    <parent link="artemis_robotiq_85_right_knuckle_link"/>
    <child link="artemis_robotiq_85_right_finger_link"/>
    <origin rpy="0 0 0" xyz="-0.03152616 0.0 -0.00376347"/>
  </joint>
  <joint name="artemis_robotiq_85_left_inner_knuckle_joint" type="continuous">
    <parent link="artemis_robotiq_85_base_link"/>
    <child link="artemis_robotiq_85_left_inner_knuckle_link"/>
    <axis xyz="0 -1 0"/>
    <origin rpy="0 0 0" xyz="0.0127 0.0 0.06142"/>
    <mimic joint="artemis_robotiq_85_left_knuckle_joint"/>
  </joint>
  <joint name="artemis_robotiq_85_right_inner_knuckle_joint" type="continuous">
    <parent link="artemis_robotiq_85_base_link"/>
    <child link="artemis_robotiq_85_right_inner_knuckle_link"/>
    <axis xyz="0 -1 0"/>
    <origin rpy="0 0 0" xyz="-0.0127 0.0 0.06142"/>
    <mimic joint="artemis_robotiq_85_left_knuckle_joint" multiplier="-1"/>
  </joint>
  <joint name="artemis_robotiq_85_left_finger_tip_joint" type="continuous">
    <parent link="artemis_robotiq_85_left_finger_link"/>
    <child link="artemis_robotiq_85_left_finger_tip_link"/>
    <axis xyz="0 -1 0"/>
    <origin rpy="0 0 0" xyz="0.00563134 0.0 0.04718515"/>
    <mimic joint="artemis_robotiq_85_left_knuckle_joint" multiplier="-1"/>
  </joint>
  <joint name="artemis_robotiq_85_right_finger_tip_joint" type="continuous">
    <parent link="artemis_robotiq_85_right_finger_link"/>
    <child link="artemis_robotiq_85_right_finger_tip_link"/>
    <axis xyz="0 -1 0"/>
    <origin rpy="0 0 0" xyz="-0.00563134 0.0 0.04718515"/>
    <mimic joint="artemis_robotiq_85_left_knuckle_joint"/>
  </joint>
  <link name="apollo_spawn_frame"/>
  <joint name="apollo_spawn_joint" type="fixed">
    <origin rpy="0 0 0" xyz="0 -2.0 0"/>
    <parent link="empty"/>
    <child link="apollo_spawn_frame"/>
    <!-- whatever the root link is -->
  </joint>
  <!-- Body Link -->
  <link name="apollo_body_link">
    <visual>
      <origin rpy="0.0 0.0 0.0" xyz="0.0 0.0 0.0"/>
      <geometry>
        <box size="0.5 0.3 0.1"/>
      </geometry>
      <material name="dark-blue-metal"/>
    </visual>
    <collision>
      <origin rpy="0.0 0.0 0.0" xyz="0.0 0.0 0.0"/>
      <geometry>
        <box size="0.5 0.3 0.1"/>
      </geometry>
    </collision>
    <inertial>
      <mass value="10"/>
      <inertia ixx="0.9812500000000001" ixy="0.0" ixz="0.0" iyy="2.55125" iyz="0" izz="3.3362499999999997"/>
      <origin rpy="0 0 0" xyz="0 0 0"/>
    </inertial>
  </link>
  <joint name="apollo_base_to_body" type="fixed">
    <parent link="apollo_spawn_frame"/>
    <child link="apollo_body_link"/>
    <origin rpy="0 0 0" xyz="0 0 0.15"/>
  </joint>
  <!-- Left Wheel -->
  <link name="apollo_left_wheel_link">
    <visual>
      <origin rpy="1.570795 0.0 0.0" xyz="0.0 0.0 0.0"/>
      <geometry>
        <cylinder length="0.05" radius="0.1"/>
      </geometry>
      <material name="dark-purple-metal"/>
    </visual>
    <collision>
      <origin rpy="1.570795 0.0 0.0" xyz="0.0 0.0 0.0"/>
      <geometry>
        <cylinder length="0.05" radius="0.1"/>
      </geometry>
      <surface>
        <friction>
          <ode>
            <mu>1</mu>
            <mu2>1</mu2>
            <slip1>0.035</slip1>
            <slip2>0</slip2>
            <fdir1>0 0 1</fdir1>
          </ode>
          <bullet>
            <friction>1</friction>
            <friction2>1</friction2>
            <rolling_friction>0.1</rolling_friction>
          </bullet>
        </friction>
      </surface>
    </collision>
    <inertial>
      <mass value="2"/>
      <inertia ixx="0.0038288160421875023" ixy="0.0" ixz="0.0" iyy="0.0038288160421875023" iyz="0" izz="0.007068583462500003"/>
      <origin rpy="1.570795 0.0 0.0" xyz="0.0 0.0 0.0"/>
    </inertial>
  </link>
  <!-- Right Wheel -->
  <link name="apollo_right_wheel_link">
    <visual>
      <origin rpy="1.570795 0.0 0.0" xyz="0.0 0.0 0.0"/>
      <geometry>
        <cylinder length="0.05" radius="0.1"/>
      </geometry>
      <material name="dark-purple-metal"/>
    </visual>
    <collision>
      <origin rpy="1.570795 0.0 0.0" xyz="0.0 0.0 0.0"/>
      <geometry>
        <cylinder length="0.05" radius="0.1"/>
      </geometry>
      <surface>
        <friction>
          <ode>
            <mu>1</mu>
            <mu2>1</mu2>
            <slip1>0.035</slip1>
            <slip2>0</slip2>
            <fdir1>0 0 1</fdir1>
          </ode>
          <bullet>
            <friction>1</friction>
            <friction2>1</friction2>
            <rolling_friction>0.1</rolling_friction>
          </bullet>
        </friction>
      </surface>
    </collision>
    <inertial>
      <mass value="2"/>
      <inertia ixx="0.0038288160421875023" ixy="0.0" ixz="0.0" iyy="0.0038288160421875023" iyz="0" izz="0.007068583462500003"/>
      <origin rpy="1.570795 0.0 0.0" xyz="0.0 0.0 0.0"/>
    </inertial>
  </link>
  <!-- Caster Wheel -->
  <link name="apollo_caster_link">
    <visual>
      <origin rpy="0.0 0.0 0.0" xyz="0.0 0.0 0.0"/>
      <geometry>
        <sphere radius="0.1"/>
      </geometry>
      <material name="metallic-green"/>
    </visual>
    <collision>
      <origin rpy="0.0 0.0 0.0" xyz="0.0 0.0 0.0"/>
      <geometry>
        <sphere radius="0.1"/>
      </geometry>
    </collision>
    <inertial>
      <mass value="0.5"/>
      <inertia ixx="1.6755160800000006e-06" ixy="0.0" ixz="0.0" iyy="1.6755160800000006e-06" iyz="0" izz="1.6755160800000006e-06"/>
      <origin rpy="0 0 0" xyz="0 0 0"/>
    </inertial>
  </link>
  <!-- Joints -->
  <!-- Left Wheel Joint -->
  <joint name="apollo_left_wheel_joint" type="continuous">
    <origin rpy="0 0 0" xyz="-0.15 0.175 -0.05"/>
    <parent link="apollo_body_link"/>
    <child link="apollo_left_wheel_link"/>
    <axis xyz="0 1 0"/>
    <limit effort="100" velocity="10.0"/>
    <dynamics damping="0.1" friction="0.1"/>
  </joint>
  <!-- Right Wheel Joint -->
  <joint name="apollo_right_wheel_joint" type="continuous">
    <origin rpy="0 0 0" xyz="-0.15 -0.175 -0.05"/>
    <parent link="apollo_body_link"/>
    <child link="apollo_right_wheel_link"/>
    <axis xyz="0 1 0"/>
    <limit effort="100" velocity="10.0"/>
    <dynamics damping="0.1" friction="0.1"/>
  </joint>
  <!-- Caster Wheel Joint (fixed) -->
  <joint name="apollo_caster_joint" type="fixed">
    <origin rpy="0 0 0" xyz="0.15 0 -0.05"/>
    <parent link="apollo_body_link"/>
    <child link="apollo_caster_link"/>
  </joint>
  <!-- links -  main serial chain -->
  <!-- base_link serves as the root of the robot's kinematic tree. It follows REP-103
        conventions (i.e., X+ forward, Y+ left, Z+ up).
        Since some kinematic solvers forbid having inertia values attached to a root link, we've
        added the base_link_inertia link that carries the visual, collision and inertia
        information.
    -->
  <link name="apollo_base_link"/>
  <link name="apollo_base_link_inertia">
    <visual>
      <origin rpy="0 0 3.141592653589793" xyz="0 0 0"/>
      <geometry>
        <mesh filename="file:///opt/ros/jazzy/share/ur_description/meshes/ur3/visual/base.dae"/>
      </geometry>
    </visual>
    <collision>
      <origin rpy="0 0 3.141592653589793" xyz="0 0 0"/>
      <geometry>
        <mesh filename="file:///opt/ros/jazzy/share/ur_description/meshes/ur3/collision/base.stl"/>
      </geometry>
    </collision>
    <inertial>
      <mass value="2.0"/>
      <origin rpy="0 0 0" xyz="0 0 0"/>
      <inertia ixx="0.0030531654454" ixy="0.0" ixz="0.0" iyy="0.0030531654454" iyz="0.0" izz="0.005625"/>
    </inertial>
  </link>
  <link name="apollo_shoulder_link">
    <visual>
      <origin rpy="0 0 3.141592653589793" xyz="0 0 0"/>
      <geometry>
        <mesh filename="file:///opt/ros/jazzy/share/ur_description/meshes/ur3/visual/shoulder.dae"/>
      </geometry>
    </visual>
    <collision>
      <origin rpy="0 0 3.141592653589793" xyz="0 0 0"/>
      <geometry>
        <mesh filename="file:///opt/ros/jazzy/share/ur_description/meshes/ur3/collision/shoulder.stl"/>
      </geometry>
    </collision>
    <inertial>
      <mass value="2.0"/>
      <origin rpy="0 0 0" xyz="0.0 0.0 -0.02"/>
      <inertia ixx="0.008093166666666665" ixy="0" ixz="0" iyy="0.008093166666666665" iyz="0" izz="0.005625"/>
    </inertial>
  </link>
  <link name="apollo_upper_arm_link">
    <visual>
      <origin rpy="1.5707963267948966 0 -1.5707963267948966" xyz="0 0 0.1198"/>
      <geometry>
        <mesh filename="file:///opt/ros/jazzy/share/ur_description/meshes/ur3/visual/upperarm.dae"/>
      </geometry>
    </visual>
    <collision>
      <origin rpy="1.5707963267948966 0 -1.5707963267948966" xyz="0 0 0.1198"/>
      <geometry>
        <mesh filename="file:///opt/ros/jazzy/share/ur_description/meshes/ur3/collision/upperarm.stl"/>
      </geometry>
    </collision>
    <inertial>
      <mass value="3.42"/>
      <origin rpy="0 1.570796326794897 0" xyz="-0.11365 0.0 0.1157"/>
      <inertia ixx="0.021728491912499998" ixy="0" ixz="0" iyy="0.021728491912499998" iyz="0" izz="0.00961875"/>
    </inertial>
  </link>
  <link name="apollo_forearm_link">
    <visual>
      <origin rpy="1.5707963267948966 0 -1.5707963267948966" xyz="0 0 0.0275"/>
      <geometry>
        <mesh filename="file:///opt/ros/jazzy/share/ur_description/meshes/ur3/visual/forearm.dae"/>
      </geometry>
    </visual>
    <collision>
      <origin rpy="1.5707963267948966 0 -1.5707963267948966" xyz="0 0 0.0275"/>
      <geometry>
        <mesh filename="file:///opt/ros/jazzy/share/ur_description/meshes/ur3/collision/forearm.stl"/>
      </geometry>
    </collision>
    <inertial>
      <mass value="1.26"/>
      <origin rpy="0 1.570796326794897 0" xyz="-0.16325 0.0 0.0238"/>
      <inertia ixx="0.0065468090625" ixy="0" ixz="0" iyy="0.0065468090625" iyz="0" izz="0.00354375"/>
    </inertial>
  </link>
  <link name="apollo_wrist_1_link">
    <visual>
      <origin rpy="1.5707963267948966 0 0" xyz="0 0 -0.085"/>
      <geometry>
        <mesh filename="file:///opt/ros/jazzy/share/ur_description/meshes/ur3/visual/wrist1.dae"/>
      </geometry>
    </visual>
    <collision>
      <origin rpy="1.5707963267948966 0 0" xyz="0 0 -0.085"/>
      <geometry>
        <mesh filename="file:///opt/ros/jazzy/share/ur_description/meshes/ur3/collision/wrist1.stl"/>
      </geometry>
    </collision>
    <inertial>
      <mass value="0.8"/>
      <origin rpy="0 0 0" xyz="0.0 -0.01 0.0"/>
      <inertia ixx="0.0016106414999999998" ixy="0" ixz="0" iyy="0.0016106414999999998" iyz="0" izz="0.00225"/>
    </inertial>
  </link>
  <link name="apollo_wrist_2_link">
    <visual>
      <origin rpy="0 0 0" xyz="0 0 -0.083"/>
      <geometry>
        <mesh filename="file:///opt/ros/jazzy/share/ur_description/meshes/ur3/visual/wrist2.dae"/>
      </geometry>
    </visual>
    <collision>
      <origin rpy="0 0 0" xyz="0 0 -0.083"/>
      <geometry>
        <mesh filename="file:///opt/ros/jazzy/share/ur_description/meshes/ur3/collision/wrist2.stl"/>
      </geometry>
    </collision>
    <inertial>
      <mass value="0.8"/>
      <origin rpy="0 0 0" xyz="0.0 0.01 0.0"/>
      <inertia ixx="0.0015721739999999998" ixy="0" ixz="0" iyy="0.0015721739999999998" iyz="0" izz="0.00225"/>
    </inertial>
  </link>
  <link name="apollo_wrist_3_link">
    <visual>
      <origin rpy="1.5707963267948966 0 0" xyz="0 -0.00255 -0.082"/>
      <geometry>
        <mesh filename="file:///opt/ros/jazzy/share/ur_description/meshes/ur3/visual/wrist3.dae"/>
      </geometry>
    </visual>
    <collision>
      <origin rpy="1.5707963267948966 0 0" xyz="0 -0.00255 -0.082"/>
      <geometry>
        <mesh filename="file:///opt/ros/jazzy/share/ur_description/meshes/ur3/collision/wrist3.stl"/>
      </geometry>
    </collision>
    <inertial>
      <mass value="0.35"/>
      <origin rpy="0 0 0" xyz="0.0 0.0 -0.02"/>
      <inertia ixx="0.00013626666666666665" ixy="0" ixz="0" iyy="0.00013626666666666665" iyz="0" izz="0.0001792"/>
    </inertial>
  </link>
  <!-- base_joint fixes base_link to the environment -->
  <joint name="apollo_base_joint" type="fixed">
    <origin rpy="0 0 0" xyz="0 0 0"/>
    <parent link="apollo_body_link"/>
    <child link="apollo_base_link"/>
  </joint>
  <!-- joints - main serial chain -->
  <joint name="apollo_base_link-base_link_inertia" type="fixed">
    <parent link="apollo_base_link"/>
    <child link="apollo_base_link_inertia"/>
    <!-- 'base_link' is REP-103 aligned (so X+ forward), while the internal
           frames of the robot/controller have X+ pointing backwards.
           Use the joint between 'base_link' and 'base_link_inertia' (a dummy
           link/frame) to introduce the necessary rotation over Z (of pi rad).
      -->
    <origin rpy="0 0 3.141592653589793" xyz="0 0 0"/>
  </joint>
  <joint name="apollo_shoulder_pan_joint" type="revolute">
    <parent link="apollo_base_link_inertia"/>
    <child link="apollo_shoulder_link"/>
    <origin rpy="0 0 0" xyz="0 0 0.1519"/>
    <axis xyz="0 0 1"/>
    <limit effort="56.0" lower="-6.283185307179586" upper="6.283185307179586" velocity="3.141592653589793"/>
    <dynamics damping="0" friction="0"/>
  </joint>
  <joint name="apollo_shoulder_lift_joint" type="revolute">
    <parent link="apollo_shoulder_link"/>
    <child link="apollo_upper_arm_link"/>
    <origin rpy="1.570796327 0 0" xyz="0 0 0"/>
    <axis xyz="0 0 1"/>
    <limit effort="56.0" lower="-6.283185307179586" upper="6.283185307179586" velocity="3.141592653589793"/>
    <dynamics damping="0" friction="0"/>
  </joint>
  <joint name="apollo_elbow_joint" type="revolute">
    <parent link="apollo_upper_arm_link"/>
    <child link="apollo_forearm_link"/>
    <origin rpy="0 0 0" xyz="-0.24365 0 0"/>
    <axis xyz="0 0 1"/>
    <limit effort="28.0" lower="-3.141592653589793" upper="3.141592653589793" velocity="3.141592653589793"/>
    <dynamics damping="0" friction="0"/>
  </joint>
  <joint name="apollo_wrist_1_joint" type="revolute">
    <parent link="apollo_forearm_link"/>
    <child link="apollo_wrist_1_link"/>
    <origin rpy="0 0 0" xyz="-0.21325 0 0.11235"/>
    <axis xyz="0 0 1"/>
    <limit effort="12.0" lower="-6.283185307179586" upper="6.283185307179586" velocity="6.283185307179586"/>
    <dynamics damping="0" friction="0"/>
  </joint>
  <joint name="apollo_wrist_2_joint" type="revolute">
    <parent link="apollo_wrist_1_link"/>
    <child link="apollo_wrist_2_link"/>
    <origin rpy="1.570796327 0 0" xyz="0 -0.08535 -1.750557762378351e-11"/>
    <axis xyz="0 0 1"/>
    <limit effort="12.0" lower="-6.283185307179586" upper="6.283185307179586" velocity="6.283185307179586"/>
    <dynamics damping="0" friction="0"/>
  </joint>
  <joint name="apollo_wrist_3_joint" type="continuous">
    <parent link="apollo_wrist_2_link"/>
    <child link="apollo_wrist_3_link"/>
    <origin rpy="1.570796326589793 3.141592653589793 3.141592653589793" xyz="0 0.0819 -1.679797079540562e-11"/>
    <axis xyz="0 0 1"/>
    <limit effort="12.0" velocity="6.283185307179586"/>
    <dynamics damping="0" friction="0"/>
  </joint>
  <link name="apollo_ft_frame"/>
  <joint name="apollo_wrist_3_link-ft_frame" type="fixed">
    <parent link="apollo_wrist_3_link"/>
    <child link="apollo_ft_frame"/>
    <origin rpy="3.141592653589793 0 0" xyz="0 0 0"/>
  </joint>
  <!-- ROS-Industrial 'base' frame - base_link to UR 'Base' Coordinates transform -->
  <link name="apollo_base"/>
  <joint name="apollo_base_link-base_fixed_joint" type="fixed">
    <!-- Note the rotation over Z of pi radians - as base_link is REP-103
           aligned (i.e., has X+ forward, Y+ left and Z+ up), this is needed
           to correctly align 'base' with the 'Base' coordinate system of
           the UR controller.
      -->
    <origin rpy="0 0 3.141592653589793" xyz="0 0 0"/>
    <parent link="apollo_base_link"/>
    <child link="apollo_base"/>
  </joint>
  <!-- ROS-Industrial 'flange' frame - attachment point for EEF models -->
  <link name="apollo_flange"/>
  <joint name="apollo_wrist_3-flange" type="fixed">
    <parent link="apollo_wrist_3_link"/>
    <child link="apollo_flange"/>
    <origin rpy="0 -1.5707963267948966 -1.5707963267948966" xyz="0 0 0"/>
  </joint>
  <!-- ROS-Industrial 'tool0' frame - all-zeros tool frame -->
  <link name="apollo_tool0"/>
  <joint name="apollo_flange-tool0" type="fixed">
    <!-- default toolframe - X+ left, Y+ up, Z+ front -->
    <origin rpy="1.5707963267948966 0 1.5707963267948966" xyz="0 0 0"/>
    <parent link="apollo_flange"/>
    <child link="apollo_tool0"/>
  </joint>
  <!-- ros2 control instance -->
  <joint name="apollo_ur_to_robotiq_joint" type="fixed">
    <!-- The parent link must be read from the robot model it is attached to. -->
    <parent link="apollo_tool0"/>
    <child link="apollo_ur_to_robotiq_link"/>
    <origin rpy="0 0 0.0" xyz="0 0 0"/>
  </joint>
  <link name="apollo_ur_to_robotiq_link">
    <visual>
      <origin rpy="0 0 0" xyz="0 0 0"/>
      <geometry>
        <mesh filename="file:///opt/ros/jazzy/share/robotiq_description/meshes/visual/ur_to_robotiq_adapter.dae"/>
      </geometry>
    </visual>
    <collision>
      <origin rpy="0 0 0" xyz="0 0 0"/>
      <geometry>
        <mesh filename="file:///opt/ros/jazzy/share/robotiq_description/meshes/collision/ur_to_robotiq_adapter.stl"/>
      </geometry>
    </collision>
    <inertial>
      <mass value="0.01"/>
      <origin xyz="0 0 0"/>
      <inertia ixx="0.000044" ixy="0.0" ixz="0.0" iyy="0.000027" iyz="0.0" izz="0.000027"/>
    </inertial>
  </link>
  <joint name="apollo_gripper_side_joint" type="fixed">
    <parent link="apollo_ur_to_robotiq_link"/>
    <child link="apollo_gripper_mount_link"/>
    <!-- <origin xyz="0 0 0.011" rpy="0 ${-pi/2} ${pi/2}"/> -->
    <origin rpy="0 0 0" xyz="0 0 0.011"/>
  </joint>
  <link name="apollo_gripper_mount_link"/>
  <!-- camera body, with origin at bottom screw mount -->
  <joint name="apollo__camera_joint" type="fixed">
    <origin rpy="0 -1.570795 1.570795" xyz="0 0.08 0"/>
    <parent link="apollo_gripper_mount_link"/>
    <child link="apollo__camera_bottom_screw_frame"/>
  </joint>
  <link name="apollo__camera_bottom_screw_frame"/>
  <joint name="apollo__camera_link_joint" type="fixed">
    <origin rpy="0 0 0" xyz="0.01085 0.009 0.021"/>
    <parent link="apollo__camera_bottom_screw_frame"/>
    <child link="apollo__camera_link"/>
  </joint>
  <link name="apollo__camera_link">
    <visual>
      <!-- the mesh origin is at front plate in between the two infrared camera axes -->
      <origin rpy="1.5707963267948966 0 1.5707963267948966" xyz="0.0038 -0.009 0"/>
      <geometry>
        <mesh filename="file:///opt/ros/jazzy/share/realsense2_description/meshes/d405.stl" scale="0.001 0.001 0.001"/>
      </geometry>
      <material name="aluminum"/>
    </visual>
    <collision>
      <origin rpy="0 0 0" xyz="-0.0078 -0.009 0"/>
      <geometry>
        <box size="0.023 0.042 0.042"/>
      </geometry>
    </collision>
    <inertial>
      <!-- The following are not reliable values, and should not be used for modeling -->
      <mass value="0.072"/>
      <origin xyz="0 0 0"/>
      <inertia ixx="0.003881243" ixy="0.0" ixz="0.0" iyy="0.000498940" iyz="0.0" izz="0.003879257"/>
    </inertial>
  </link>
  <!-- camera depth joints and links -->
  <joint name="apollo__camera_depth_joint" type="fixed">
    <origin rpy="0 0 0" xyz="0 0 0"/>
    <parent link="apollo__camera_link"/>
    <child link="apollo__camera_depth_frame"/>
  </joint>
  <link name="apollo__camera_depth_frame"/>
  <joint name="apollo__camera_depth_optical_joint" type="fixed">
    <origin rpy="-1.5707963267948966 0 -1.5707963267948966" xyz="0 0 0"/>
    <parent link="apollo__camera_depth_frame"/>
    <child link="apollo__camera_depth_optical_frame"/>
  </joint>
  <link name="apollo__camera_depth_optical_frame"/>
  <!-- camera left IR joints and links -->
  <joint name="apollo__camera_infra1_joint" type="fixed">
    <origin rpy="0 0 0" xyz="0 0.0 0"/>
    <parent link="apollo__camera_link"/>
    <child link="apollo__camera_infra1_frame"/>
  </joint>
  <link name="apollo__camera_infra1_frame"/>
  <joint name="apollo__camera_infra1_optical_joint" type="fixed">
    <origin rpy="-1.5707963267948966 0 -1.5707963267948966" xyz="0 0 0"/>
    <parent link="apollo__camera_infra1_frame"/>
    <child link="apollo__camera_infra1_optical_frame"/>
  </joint>
  <link name="apollo__camera_infra1_optical_frame"/>
  <!-- camera right IR joints and links -->
  <joint name="apollo__camera_infra2_joint" type="fixed">
    <origin rpy="0 0 0" xyz="0 -0.018 0"/>
    <parent link="apollo__camera_link"/>
    <child link="apollo__camera_infra2_frame"/>
  </joint>
  <link name="apollo__camera_infra2_frame"/>
  <joint name="apollo__camera_infra2_optical_joint" type="fixed">
    <origin rpy="-1.5707963267948966 0 -1.5707963267948966" xyz="0 0 0"/>
    <parent link="apollo__camera_infra2_frame"/>
    <child link="apollo__camera_infra2_optical_frame"/>
  </joint>
  <link name="apollo__camera_infra2_optical_frame"/>
  <!-- camera color joints and links -->
  <joint name="apollo__camera_color_joint" type="fixed">
    <origin rpy="0 0 0" xyz="0 0.0 0"/>
    <parent link="apollo__camera_link"/>
    <child link="apollo__camera_color_frame"/>
  </joint>
  <link name="apollo__camera_color_frame"/>
  <joint name="apollo__camera_color_optical_joint" type="fixed">
    <origin rpy="-1.5707963267948966 0 -1.5707963267948966" xyz="0 0 0"/>
    <parent link="apollo__camera_color_frame"/>
    <child link="apollo__camera_color_optical_frame"/>
  </joint>
  <link name="apollo__camera_color_optical_frame"/>
  <link name="apollo_robotiq_85_base_link">
    <visual>
      <geometry>
        <mesh filename="file:///opt/ros/jazzy/share/robotiq_description/meshes/visual/robotiq_base.dae"/>
      </geometry>
    </visual>
    <collision>
      <geometry>
        <mesh filename="file:///opt/ros/jazzy/share/robotiq_description/meshes/collision/robotiq_base.stl"/>
      </geometry>
    </collision>
    <inertial>
      <origin rpy="0 0 0" xyz="0.0 2.274e-05 0.03232288"/>
      <mass value="6.6320197e-01"/>
      <inertia ixx="5.1617816e-04" ixy="2.936e-8" ixz="0.0" iyy="5.8802208e-04" iyz="-3.2296e-7" izz="3.9462776e-04"/>
    </inertial>
  </link>
  <link name="apollo_robotiq_85_left_knuckle_link">
    <visual>
      <geometry>
        <mesh filename="file:///opt/ros/jazzy/share/robotiq_description/meshes/visual/left_knuckle.dae"/>
      </geometry>
    </visual>
    <collision>
      <geometry>
        <mesh filename="file:///opt/ros/jazzy/share/robotiq_description/meshes/collision/left_knuckle.stl"/>
      </geometry>
    </collision>
    <inertial>
      <origin rpy="0 0 0" xyz="0.01213197 0.0002 -0.00058647"/>
      <mass value="1.384773208e-02"/>
      <inertia ixx="3.5232e-7" ixy="0.0" ixz="1.1744e-7" iyy="2.31944e-6" iyz="0" izz="2.23136e-6"/>
    </inertial>
  </link>
  <link name="apollo_robotiq_85_right_knuckle_link">
    <visual>
      <geometry>
        <mesh filename="file:///opt/ros/jazzy/share/robotiq_description/meshes/visual/right_knuckle.dae"/>
      </geometry>
    </visual>
    <collision>
      <geometry>
        <mesh filename="file:///opt/ros/jazzy/share/robotiq_description/meshes/collision/right_knuckle.stl"/>
      </geometry>
    </collision>
    <inertial>
      <origin rpy="0 0 0" xyz="-0.01213197 0.0002 -0.00058647"/>
      <mass value="1.384773208e-02"/>
      <inertia ixx="3.5232e-7" ixy="0.0" ixz="-1.1744e-7" iyy="2.31944e-6" iyz="0.0" izz="2.23136e-6"/>
    </inertial>
  </link>
  <link name="apollo_robotiq_85_left_finger_link">
    <visual>
      <geometry>
        <mesh filename="file:///opt/ros/jazzy/share/robotiq_description/meshes/visual/left_finger.dae"/>
      </geometry>
    </visual>
    <collision>
      <geometry>
        <mesh filename="file:///opt/ros/jazzy/share/robotiq_description/meshes/collision/left_finger.stl"/>
      </geometry>
    </collision>
    <inertial>
      <origin rpy="0 0 0" xyz="0.00346899 -0.00079447 0.01867121"/>
      <mass value="4.260376752e-02"/>
      <inertia ixx="1.385792000000000e-05" ixy="0.0" ixz="-2.17264e-06" iyy="1.183208e-05" iyz="0.0" izz="5.19672e-06"/>
    </inertial>
  </link>
  <link name="apollo_robotiq_85_right_finger_link">
    <visual>
      <geometry>
        <mesh filename="file:///opt/ros/jazzy/share/robotiq_description/meshes/visual/right_finger.dae"/>
      </geometry>
    </visual>
    <collision>
      <geometry>
        <mesh filename="file:///opt/ros/jazzy/share/robotiq_description/meshes/collision/right_finger.stl"/>
      </geometry>
    </collision>
    <inertial>
      <origin rpy="0 0 0" xyz="-0.00346899 -5.53e-06 0.01867121"/>
      <mass value="4.260376752000000e-02"/>
      <inertia ixx="1.385792e-05" ixy="0.0" ixz="2.17264e-06" iyy="1.183208e-05" iyz="0.0" izz="5.19672e-06"/>
    </inertial>
  </link>
  <link name="apollo_robotiq_85_left_inner_knuckle_link">
    <visual>
      <geometry>
        <mesh filename="file:///opt/ros/jazzy/share/robotiq_description/meshes/visual/left_inner_knuckle.dae"/>
      </geometry>
    </visual>
    <collision>
      <geometry>
        <mesh filename="file:///opt/ros/jazzy/share/robotiq_description/meshes/collision/left_inner_knuckle.stl"/>
      </geometry>
    </collision>
    <inertial>
      <origin rpy="0 0 0" xyz="0.01897699 0.00015001 0.02247101"/>
      <mass value="2.969376448e-02"/>
      <inertia ixx="9.57136e-06" ixy="0.0" ixz="-3.93424e-06" iyy="8.69056e-06" iyz="0.0" izz="8.19144e-06"/>
    </inertial>
  </link>
  <link name="apollo_robotiq_85_right_inner_knuckle_link">
    <visual>
      <geometry>
        <mesh filename="file:///opt/ros/jazzy/share/robotiq_description/meshes/visual/right_inner_knuckle.dae"/>
      </geometry>
    </visual>
    <collision>
      <geometry>
        <mesh filename="file:///opt/ros/jazzy/share/robotiq_description/meshes/collision/right_inner_knuckle.stl"/>
      </geometry>
    </collision>
    <inertial>
      <origin rpy="0 0 0" xyz="-0.01926824 5.001e-05 0.02222178"/>
      <mass value="2.969376448e-02"/>
      <inertia ixx="9.42456e-06" ixy="0.0" ixz="3.9636e-06" iyy="8.69056e-06" iyz="0.0" izz="8.33824e-06"/>
    </inertial>
  </link>
  <link name="apollo_robotiq_85_left_finger_tip_link">
    <visual>
      <geometry>
        <mesh filename="file:///opt/ros/jazzy/share/robotiq_description/meshes/visual/left_finger_tip.dae"/>
      </geometry>
    </visual>
    <collision>
      <geometry>
        <mesh filename="file:///opt/ros/jazzy/share/robotiq_description/meshes/collision/left_finger_tip.stl"/>
      </geometry>
      <surface>
        <friction>
          <ode>
            <mu1>100000.0</mu1>
            <mu2>100000.0</mu2>
          </ode>
        </friction>
        <contact>
          <ode>
            <kp>1e+5</kp>
            <kd>1</kd>
            <soft_cfm>0</soft_cfm>
            <soft_erp>0.2</soft_erp>
            <minDepth>0.002</minDepth>
            <maxVel>0</maxVel>
          </ode>
        </contact>
      </surface>
    </collision>
    <inertial>
      <origin rpy="0 0 0" xyz="-0.01456706 -0.0008 0.01649701"/>
      <mass value="4.268588744e-02"/>
      <inertia ixx="1.048152e-05" ixy="0.0" ixz="3.5232e-6" iyy="1.197888e-05" iyz="0.0" izz="4.22784e-06"/>
    </inertial>
  </link>
  <link name="apollo_robotiq_85_right_finger_tip_link">
    <visual>
      <geometry>
        <mesh filename="file:///opt/ros/jazzy/share/robotiq_description/meshes/visual/right_finger_tip.dae"/>
      </geometry>
    </visual>
    <collision>
      <geometry>
        <mesh filename="file:///opt/ros/jazzy/share/robotiq_description/meshes/collision/right_finger_tip.stl"/>
      </geometry>
      <surface>
        <friction>
          <ode>
            <mu1>100000.0</mu1>
            <mu2>100000.0</mu2>
          </ode>
        </friction>
        <contact>
          <ode>
            <kp>1e+5</kp>
            <kd>1</kd>
            <soft_cfm>0</soft_cfm>
            <soft_erp>0.2</soft_erp>
            <minDepth>0.002</minDepth>
            <maxVel>0</maxVel>
          </ode>
        </contact>
      </surface>
    </collision>
    <inertial>
      <origin rpy="0 0 0" xyz="0.01456706 5e-05 0.01649701"/>
      <mass value="4.268588744e-02"/>
      <inertia ixx="1.048152e-05" ixy="0.0" ixz="-3.5232e-06" iyy="1.197888e-05" iyz="0.0" izz="4.22784e-06"/>
    </inertial>
  </link>
  <joint name="apollo_robotiq_85_base_joint" type="fixed">
    <parent link="apollo_gripper_mount_link"/>
    <child link="apollo_robotiq_85_base_link"/>
    <origin rpy="0 0 0" xyz="0 0 0"/>
  </joint>
  <joint name="apollo_robotiq_85_left_knuckle_joint" type="revolute">
    <parent link="apollo_robotiq_85_base_link"/>
    <child link="apollo_robotiq_85_left_knuckle_link"/>
    <axis xyz="0 -1 0"/>
    <origin rpy="0 0 0" xyz="0.03060114 0.0 0.05490452"/>
    <limit effort="50" lower="0.0" upper="0.8" velocity="0.5"/>
  </joint>
  <joint name="apollo_robotiq_85_right_knuckle_joint" type="revolute">
    <parent link="apollo_robotiq_85_base_link"/>
    <child link="apollo_robotiq_85_right_knuckle_link"/>
    <axis xyz="0 -1 0"/>
    <origin rpy="0 0 0" xyz="-0.03060114 0.0 0.05490452"/>
    <limit effort="50" lower="-0.8" upper="0.0" velocity="0.5"/>
    <mimic joint="apollo_robotiq_85_left_knuckle_joint" multiplier="-1"/>
  </joint>
  <joint name="apollo_robotiq_85_left_finger_joint" type="fixed">
    <parent link="apollo_robotiq_85_left_knuckle_link"/>
    <child link="apollo_robotiq_85_left_finger_link"/>
    <origin rpy="0 0 0" xyz="0.03152616 0.0 -0.00376347"/>
  </joint>
  <joint name="apollo_robotiq_85_right_finger_joint" type="fixed">
    <parent link="apollo_robotiq_85_right_knuckle_link"/>
    <child link="apollo_robotiq_85_right_finger_link"/>
    <origin rpy="0 0 0" xyz="-0.03152616 0.0 -0.00376347"/>
  </joint>
  <joint name="apollo_robotiq_85_left_inner_knuckle_joint" type="continuous">
    <parent link="apollo_robotiq_85_base_link"/>
    <child link="apollo_robotiq_85_left_inner_knuckle_link"/>
    <axis xyz="0 -1 0"/>
    <origin rpy="0 0 0" xyz="0.0127 0.0 0.06142"/>
    <mimic joint="apollo_robotiq_85_left_knuckle_joint"/>
  </joint>
  <joint name="apollo_robotiq_85_right_inner_knuckle_joint" type="continuous">
    <parent link="apollo_robotiq_85_base_link"/>
    <child link="apollo_robotiq_85_right_inner_knuckle_link"/>
    <axis xyz="0 -1 0"/>
    <origin rpy="0 0 0" xyz="-0.0127 0.0 0.06142"/>
    <mimic joint="apollo_robotiq_85_left_knuckle_joint" multiplier="-1"/>
  </joint>
  <joint name="apollo_robotiq_85_left_finger_tip_joint" type="continuous">
    <parent link="apollo_robotiq_85_left_finger_link"/>
    <child link="apollo_robotiq_85_left_finger_tip_link"/>
    <axis xyz="0 -1 0"/>
    <origin rpy="0 0 0" xyz="0.00563134 0.0 0.04718515"/>
    <mimic joint="apollo_robotiq_85_left_knuckle_joint" multiplier="-1"/>
  </joint>
  <joint name="apollo_robotiq_85_right_finger_tip_joint" type="continuous">
    <parent link="apollo_robotiq_85_right_finger_link"/>
    <child link="apollo_robotiq_85_right_finger_tip_link"/>
    <axis xyz="0 -1 0"/>
    <origin rpy="0 0 0" xyz="-0.00563134 0.0 0.04718515"/>
    <mimic joint="apollo_robotiq_85_left_knuckle_joint"/>
  </joint>
  <ros2_control name="artemis_devol_ros2_control" type="system">
    <hardware>
      <!-- Use Gazebo plugin for simulation -->
      <plugin>gz_ros2_control/GazeboSimSystem</plugin>
    </hardware>
    <joint name="artemis_shoulder_pan_joint">
      <command_interface name="position"/>
      <state_interface name="position">
        <param name="initial_value">3.14159</param>
      </state_interface>
      <state_interface name="velocity"/>
    </joint>
    <joint name="artemis_shoulder_lift_joint">
      <command_interface name="position"/>
      <state_interface name="position">
        <param name="initial_value">0.0</param>
      </state_interface>
      <state_interface name="velocity"/>
    </joint>
    <joint name="artemis_elbow_joint">
      <command_interface name="position"/>
      <state_interface name="position">
        <param name="initial_value">0.0</param>
      </state_interface>
      <state_interface name="velocity"/>
    </joint>
    <joint name="artemis_wrist_1_joint">
      <command_interface name="position"/>
      <state_interface name="position">
        <param name="initial_value">0.0</param>
      </state_interface>
      <state_interface name="velocity"/>
    </joint>
    <joint name="artemis_wrist_2_joint">
      <command_interface name="position"/>
      <state_interface name="position">
        <param name="initial_value">0.0</param>
      </state_interface>
      <state_interface name="velocity"/>
    </joint>
    <joint name="artemis_wrist_3_joint">
      <command_interface name="position"/>
      <state_interface name="position">
        <param name="initial_value">0.0</param>
      </state_interface>
      <state_interface name="velocity"/>
    </joint>
    <joint name="artemis_robotiq_85_left_knuckle_joint">
      <command_interface name="position"/>
      <state_interface name="position">
        <param name="initial_value">0.0</param>
      </state_interface>
      <state_interface name="velocity"/>
    </joint>
    <joint name="artemis_robotiq_85_right_knuckle_joint"/>
    <joint name="artemis_robotiq_85_left_inner_knuckle_joint"/>
    <joint name="artemis_robotiq_85_right_inner_knuckle_joint"/>
    <joint name="artemis_robotiq_85_left_finger_tip_joint"/>
    <joint name="artemis_robotiq_85_right_finger_tip_joint"/>
  </ros2_control>
  <ros2_control name="artemis_diff_drive_ros2_control" type="system">
    <hardware>
      <!-- Use Gazebo plugin for simulation -->
      <plugin>gz_ros2_control/GazeboSimSystem</plugin>
    </hardware>
    <joint name="artemis_left_wheel_joint">
      <command_interface name="position"/>
      <state_interface name="position">
        <param name="initial_value">0</param>
      </state_interface>
      <state_interface name="velocity"/>
    </joint>
    <joint name="artemis_right_wheel_joint">
      <command_interface name="position"/>
      <state_interface name="position">
        <param name="initial_value">0</param>
      </state_interface>
      <state_interface name="velocity"/>
    </joint>
  </ros2_control>
  <ros2_control name="apollo_devol_ros2_control" type="system">
    <hardware>
      <!-- Use Gazebo plugin for simulation -->
      <plugin>gz_ros2_control/GazeboSimSystem</plugin>
    </hardware>
    <joint name="apollo_shoulder_pan_joint">
      <command_interface name="position"/>
      <state_interface name="position">
        <param name="initial_value">3.14159</param>
      </state_interface>
      <state_interface name="velocity"/>
    </joint>
    <joint name="apollo_shoulder_lift_joint">
      <command_interface name="position"/>
      <state_interface name="position">
        <param name="initial_value">0.0</param>
      </state_interface>
      <state_interface name="velocity"/>
    </joint>
    <joint name="apollo_elbow_joint">
      <command_interface name="position"/>
      <state_interface name="position">
        <param name="initial_value">0.0</param>
      </state_interface>
      <state_interface name="velocity"/>
    </joint>
    <joint name="apollo_wrist_1_joint">
      <command_interface name="position"/>
      <state_interface name="position">
        <param name="initial_value">0.0</param>
      </state_interface>
      <state_interface name="velocity"/>
    </joint>
    <joint name="apollo_wrist_2_joint">
      <command_interface name="position"/>
      <state_interface name="position">
        <param name="initial_value">0.0</param>
      </state_interface>
      <state_interface name="velocity"/>
    </joint>
    <joint name="apollo_wrist_3_joint">
      <command_interface name="position"/>
      <state_interface name="position">
        <param name="initial_value">0.0</param>
      </state_interface>
      <state_interface name="velocity"/>
    </joint>
    <joint name="apollo_robotiq_85_left_knuckle_joint">
      <command_interface name="position"/>
      <state_interface name="position">
        <param name="initial_value">0.0</param>
      </state_interface>
      <state_interface name="velocity"/>
    </joint>
    <joint name="apollo_robotiq_85_right_knuckle_joint"/>
    <joint name="apollo_robotiq_85_left_inner_knuckle_joint"/>
    <joint name="apollo_robotiq_85_right_inner_knuckle_joint"/>
    <joint name="apollo_robotiq_85_left_finger_tip_joint"/>
    <joint name="apollo_robotiq_85_right_finger_tip_joint"/>
  </ros2_control>
  <ros2_control name="apollo_diff_drive_ros2_control" type="system">
    <hardware>
      <!-- Use Gazebo plugin for simulation -->
      <plugin>gz_ros2_control/GazeboSimSystem</plugin>
    </hardware>
    <joint name="apollo_left_wheel_joint">
      <command_interface name="position"/>
      <state_interface name="position">
        <param name="initial_value">0</param>
      </state_interface>
      <state_interface name="velocity"/>
    </joint>
    <joint name="apollo_right_wheel_joint">
      <command_interface name="position"/>
      <state_interface name="position">
        <param name="initial_value">0</param>
      </state_interface>
      <state_interface name="velocity"/>
    </joint>
  </ros2_control>
  <gazebo>
    <plugin filename="gz_ros2_control-system" name="gz_ros2_control::GazeboSimROS2ControlPlugin">
      <parameters>/home/jakeadelic/programming/devol/install/dual_devol_description/share/dual_devol_description/config/ros2_controllers.yaml</parameters>
    </plugin>
  </gazebo>
  <!-- ros_control plugin -->
  <!-- Gazebo Parameters -->
  <gazebo reference="artemis_body_link">
    <mu1>1.0</mu1>
    <mu2>1.0</mu2>
    <material>
      <ambient>0.0 0.0 0.2 1</ambient>
      <diffuse>0.0 0.0 0.4 1</diffuse>
      <specular>0.5 0.5 0.7 1</specular>
      <emissive>0 0 0 1</emissive>
    </material>
  </gazebo>
  <gazebo reference="artemis_right_wheel_link">
    <mu1>1.0</mu1>
    <mu2>1.0</mu2>
    <material>
      <ambient>0.2 0.0 0.2 1</ambient>
      <diffuse>0.4 0.0 0.4 1</diffuse>
      <specular>0.5 0.3 0.6 1</specular>
      <emissive>0 0 0 1</emissive>
    </material>
  </gazebo>
  <gazebo reference="artemis_left_wheel_link">
    <mu1>1.0</mu1>
    <mu2>1.0</mu2>
    <material>
      <ambient>0.2 0.0 0.2 1</ambient>
      <diffuse>0.4 0.0 0.4 1</diffuse>
      <specular>0.5 0.3 0.6 1</specular>
      <emissive>0 0 0 1</emissive>
    </material>
  </gazebo>
  <gazebo reference="artemis_caster_link">
    <mu1>0.000001</mu1>
    <mu2>0.000001</mu2>
    <material>
      <ambient>0.0 0.2 0.0 1</ambient>
      <diffuse>0.0 0.5 0.0 1</diffuse>
      <specular>0.4 0.6 0.4 1</specular>
      <emissive>0 0 0 1</emissive>
    </material>
  </gazebo>
  <gazebo>
    <plugin filename="gz-sim-diff-drive-system" name="gz::sim::systems::DiffDrive">
      <left_joint>artemis_left_wheel_joint</left_joint>
      <right_joint>artemis_right_wheel_joint</right_joint>
      <topic>/model/artemis_devol_drive/cmd_vel</topic>
      <odom_topic>/model/artemis_devol_drive/odom</odom_topic>
      <wheel_separation>0.35</wheel_separation>
      <wheel_radius>0.1</wheel_radius>
      <odom_publish_frequency>1</odom_publish_frequency>
      <max_linear_acceleration>10</max_linear_acceleration>
      <min_linear_acceleration>-1</min_linear_acceleration>
      <max_angular_acceleration>2</max_angular_acceleration>
      <min_angular_acceleration>-2</min_angular_acceleration>
      <max_linear_velocity>0.5</max_linear_velocity>
      <min_linear_velocity>-0.5</min_linear_velocity>
      <max_angular_velocity>1</max_angular_velocity>
      <min_angular_velocity>-1</min_angular_velocity>
    </plugin>
  </gazebo>
  <!-- ros_control plugin -->
  <gazebo>
    <!-- <plugin filename="gz_ros2_control-system" name="gz_ros2_control::GazeboSimROS2ControlPlugin">
        <parameters>$(find devol_description)/config/ros2_controllers.yaml</parameters>
      </plugin> -->
    <plugin filename="libgz-sim-detachable-joint-system.so" name="gz::sim::systems::DetachableJoint">
      <parent_link>artemis_wrist_3_link</parent_link>
      <child_link>target_block_0</child_link>
      <child_model>target_block_0</child_model>
      <child_model_link>target_block_0</child_model_link>
      <attach_topic>/artemis_devol_attach/attach</attach_topic>
      <detach_topic>/artemis_devol_attach/detach</detach_topic>
    </plugin>
  </gazebo>
  <!-- Camera -->
  <gazebo reference="artemis__camera_color_frame">
    <sensor name="artemis_realsense_d405_camera" type="camera">
      <pose relative_to="artemis__camera_color_frame">0 0 0 3.14159 0 0</pose>
      <topic>/model/artemis_devol/color_raw</topic>
      <camera>
        <camera_info_topic>/model/artemis_devol/color_info</camera_info_topic>
        <horizontal_fov>1.518</horizontal_fov>
        <image>
          <width>1280</width>
          <height>720</height>
          <format>R8G8B8</format>
        </image>
        <clip>
          <near>0.1</near>
          <far>5.0</far>
        </clip>
      </camera>
      <always_on>1</always_on>
      <visualize>1</visualize>
      <update_rate>30</update_rate>
    </sensor>
  </gazebo>
  <!-- Depth Camera  -->
  <gazebo reference="artemis__camera_depth_frame">
    <sensor name="artemis_realsense_d405_depth_camera" type="depth_camera">
      <topic>/model/artemis_devol/depth_raw</topic>
      <pose relative_to="artemis__camera_color_frame">0 0 0 3.14159 0 0</pose>
      <camera>
        <camera_info_topic>/model/artemis_devol/depth_info</camera_info_topic>
        <horizontal_fov>1.518</horizontal_fov>
        <image>
          <width>1280</width>
          <height>720</height>
          <format>L16</format>
        </image>
        <clip>
          <near>0.1</near>
          <far>5.0</far>
        </clip>
      </camera>
      <always_on>true</always_on>
      <visualize>1</visualize>
      <update_rate>30</update_rate>
    </sensor>
  </gazebo>
  <!-- ros_control plugin -->
  <!-- Gazebo Parameters -->
  <gazebo reference="apollo_body_link">
    <mu1>1.0</mu1>
    <mu2>1.0</mu2>
    <material>
      <ambient>0.0 0.0 0.2 1</ambient>
      <diffuse>0.0 0.0 0.4 1</diffuse>
      <specular>0.5 0.5 0.7 1</specular>
      <emissive>0 0 0 1</emissive>
    </material>
  </gazebo>
  <gazebo reference="apollo_right_wheel_link">
    <mu1>1.0</mu1>
    <mu2>1.0</mu2>
    <material>
      <ambient>0.2 0.0 0.2 1</ambient>
      <diffuse>0.4 0.0 0.4 1</diffuse>
      <specular>0.5 0.3 0.6 1</specular>
      <emissive>0 0 0 1</emissive>
    </material>
  </gazebo>
  <gazebo reference="apollo_left_wheel_link">
    <mu1>1.0</mu1>
    <mu2>1.0</mu2>
    <material>
      <ambient>0.2 0.0 0.2 1</ambient>
      <diffuse>0.4 0.0 0.4 1</diffuse>
      <specular>0.5 0.3 0.6 1</specular>
      <emissive>0 0 0 1</emissive>
    </material>
  </gazebo>
  <gazebo reference="apollo_caster_link">
    <mu1>0.000001</mu1>
    <mu2>0.000001</mu2>
    <material>
      <ambient>0.0 0.2 0.0 1</ambient>
      <diffuse>0.0 0.5 0.0 1</diffuse>
      <specular>0.4 0.6 0.4 1</specular>
      <emissive>0 0 0 1</emissive>
    </material>
  </gazebo>
  <gazebo>
    <plugin filename="gz-sim-diff-drive-system" name="gz::sim::systems::DiffDrive">
      <left_joint>apollo_left_wheel_joint</left_joint>
      <right_joint>apollo_right_wheel_joint</right_joint>
      <topic>/model/apollo_devol_drive/cmd_vel</topic>
      <odom_topic>/model/apollo_devol_drive/odom</odom_topic>
      <wheel_separation>0.35</wheel_separation>
      <wheel_radius>0.1</wheel_radius>
      <odom_publish_frequency>1</odom_publish_frequency>
      <max_linear_acceleration>10</max_linear_acceleration>
      <min_linear_acceleration>-1</min_linear_acceleration>
      <max_angular_acceleration>2</max_angular_acceleration>
      <min_angular_acceleration>-2</min_angular_acceleration>
      <max_linear_velocity>0.5</max_linear_velocity>
      <min_linear_velocity>-0.5</min_linear_velocity>
      <max_angular_velocity>1</max_angular_velocity>
      <min_angular_velocity>-1</min_angular_velocity>
    </plugin>
  </gazebo>
  <!-- ros_control plugin -->
  <gazebo>
    <!-- <plugin filename="gz_ros2_control-system" name="gz_ros2_control::GazeboSimROS2ControlPlugin">
        <parameters>$(find devol_description)/config/ros2_controllers.yaml</parameters>
      </plugin> -->
    <plugin filename="libgz-sim-detachable-joint-system.so" name="gz::sim::systems::DetachableJoint">
      <parent_link>apollo_wrist_3_link</parent_link>
      <child_link>target_block_0</child_link>
      <child_model>target_block_0</child_model>
      <child_model_link>target_block_0</child_model_link>
      <attach_topic>/apollo_devol_attach/attach</attach_topic>
      <detach_topic>/apollo_devol_attach/detach</detach_topic>
    </plugin>
  </gazebo>
  <!-- Camera -->
  <gazebo reference="apollo__camera_color_frame">
    <sensor name="apollo_realsense_d405_camera" type="camera">
      <pose relative_to="apollo__camera_color_frame">0 0 0 3.14159 0 0</pose>
      <topic>/model/apollo_devol/color_raw</topic>
      <camera>
        <camera_info_topic>/model/apollo_devol/color_info</camera_info_topic>
        <horizontal_fov>1.518</horizontal_fov>
        <image>
          <width>1280</width>
          <height>720</height>
          <format>R8G8B8</format>
        </image>
        <clip>
          <near>0.1</near>
          <far>5.0</far>
        </clip>
      </camera>
      <always_on>1</always_on>
      <visualize>1</visualize>
      <update_rate>30</update_rate>
    </sensor>
  </gazebo>
  <!-- Depth Camera  -->
  <gazebo reference="apollo__camera_depth_frame">
    <sensor name="apollo_realsense_d405_depth_camera" type="depth_camera">
      <topic>/model/apollo_devol/depth_raw</topic>
      <pose relative_to="apollo__camera_color_frame">0 0 0 3.14159 0 0</pose>
      <camera>
        <camera_info_topic>/model/apollo_devol/depth_info</camera_info_topic>
        <horizontal_fov>1.518</horizontal_fov>
        <image>
          <width>1280</width>
          <height>720</height>
          <format>L16</format>
        </image>
        <clip>
          <near>0.1</near>
          <far>5.0</far>
        </clip>
      </camera>
      <always_on>true</always_on>
      <visualize>1</visualize>
      <update_rate>30</update_rate>
    </sensor>
  </gazebo>
</robot>
